Workbook

Sheet PTM
B2: INVERSIONES AÑO 2026 | V2: Abonó Int L10mil el 26/06/2026 | AK2: =2433.92+2433.95 -> 4867.87 | AN2: 7301.89 | AO2: 2433.95 | AP2: =AN2-AO2 -> 4867.94
C4: PRESTAMO 1 | G4: 0.05 | K4: PRESTAMO 2 | O4: 0.03 | T4: PRESTAMO 3 | W4: 0.02 | AB4: PRESTAMO 4 | AD4: 0.02 | AJ4: PRESTAMO 5 | AL4: 0.04 | AR4: PRESTAMO 6 | AT4: 0.035 | AZ4: PRESTAMO 7 | BC4: 0.035 | BH4: PRESTAMO 8 | BJ4: 0.045 | BO4: PRESTAMO 9 | BQ4: 0.045 | BW4: PRESTAMO 10 | BZ4: 0.05 | CF4: 0 | CH4: 0.045 | CM4: 0 | CQ4: 0.04 | CU4: 0 | CX4: 0.045 | DD4: 0 | DF4: 0.045 | DL4: 0 | DO4: 0.04 | DS4: 0 | DV4: 0.038 | EA4: 0 | EE4: 0.045 | EJ4: 0 | EL4: 0.045 | ER4: 0 | EU4: 0.045 | EY4: 0 | FB4: 0.045 | FG4: 0 | FK4: 0.04 | FO4: 0 | FS4: 0.045 | FW4: 0 | GA4: 0.025 | GE4: 0 | GI4: 0.045 | GM4: 0 | GQ4: 0.045 | GU4: 0 | GX4: 0.04 | HC4: 0 | HK4: 0 | HO4: 0.045 | HT4: 0 | IB4: 0 | IJ4: 0 | IR4: 0 | IZ4: 0 | JG4: 0 | JP4: 0 | JW4: 0 | KE4: 0 | KM4: 0 | KU4: 0 | LC4: 0 | LK4: 0 | LS4: 0 | MA4: 0 | MI4: 0 | MQ4: 0 | MY4: 0 | NG4: 0 | NO4: 0 | NW4: 0 | OE4: 0 | OM4: 0 | OU4: 0 | PC4: 0 | PK4: 0 | PS4: 0 | QA4: 0 | QI4: 0 | QQ4: 0 | QY4: 0 | RG4: 0 | RO4: 0 | RW4: 0 | SE4: 0 | SM4: 0 | SU4: 0 | TC4: 0 | TK4: 0 | TS4: 0 | UA4: 0 | UI4: 0 | UQ4: 0 | UY4: 0 | VG4: 0 | VO4: 0 | VW4: 0 | WE4: 0 | WM4: 0 | WU4: 0 | XC4: 0 | XK4: 0 | XS4: 0 | YA4: 0 | YI4: 0 | YQ4: 0 | YY4: 0 | ZG4: 0 | ZO4: 0 | ZW4: 0 | AAE4: 0 | AAM4: 0 | AAU4: 0 | ABC4: 0 | ABK4: 0 | ABS4: 0 | ACA4: 0
A5: =C4 -> PRESTAMO 1 | I5: =K4 -> PRESTAMO 2 | Q5: =T4 -> PRESTAMO 3 | Y5: =AB4 -> PRESTAMO 4 | AG5: =AJ4 -> PRESTAMO 5 | AO5: =AR4 -> PRESTAMO 6 | AW5: =AZ4 -> PRESTAMO 7 | BE5: =BH4 -> PRESTAMO 8 | BM5: =BO4 -> PRESTAMO 9 | BU5: =BW4 -> PRESTAMO 10 | CC5: =CF4 -> 0 | CK5: =CM4 -> 0 | CS5: =CU4 -> 0 | DA5: =DD4 -> 0 | DI5: =DL4 -> 0 | DQ5: =DS4 -> 0 | DY5: =EA4 -> 0 | EG5: =EJ4 -> 0 | EO5: =ER4 -> 0 | EW5: =EY4 -> 0 | FE5: =FG4 -> 0 | FM5: =FO4 -> 0 | FU5: =FW4 -> 0 | GC5: =GE4 -> 0 | GK5: =GM4 -> 0 | GS5: =GU4 -> 0 | HA5: =HC4 -> 0 | HI5: =HK4 -> 0 | HQ5: =HT4 -> 0 | HY5: =IB4 -> 0 | IG5: =IJ4 -> 0 | IR5: =IR4 -> 0 | IZ5: =IZ4 -> 0 | JE5: =JG4 -> 0 | JM5: =JP4 -> 0 | JU5: =JW4 -> 0 | KC5: =KE4 -> 0 | KK5: =KM4 -> 0 | KS5: =KU4 -> 0 | LA5: =LC4 -> 0 | LI5: =LK4 -> 0 | LS5: =LS4 -> 0 | MA5: =MA4 -> 0 | MI5: =MI4 -> 0 | MQ5: =MQ4 -> 0 | MY5: =MY4 -> 0 | NG5: =NG4 -> 0 | NO5: =NO4 -> 0 | NW5: =NW4 -> 0 | OE5: =OE4 -> 0 | OM5: =OM4 -> 0 | OU5: =OU4 -> 0 | PC5: =PC4 -> 0 | PK5: =PK4 -> 0 | PS5: =PS4 -> 0 | QA5: =QA4 -> 0 | QI5: =QI4 -> 0 | QQ5: =QQ4 -> 0 | QY5: =QY4 -> 0 | RG5: =RG4 -> 0 | RO5: =RO4 -> 0 | RW5: =RW4 -> 0 | SE5: =SE4 -> 0 | SM5: =SM4 -> 0 | SU5: =SU4 -> 0 | TC5: =TC4 -> 0 | TK5: =TK4 -> 0 | TS5: =TS4 -> 0 | UA5: =UA4 -> 0 | UI5: =UI4 -> 0 | UQ5: =UQ4 -> 0 | UY5: =UY4 -> 0 | VG5: =VG4 -> 0 | VO5: =VO4 -> 0 | VW5: =VW4 -> 0 | WE5: =WE4 -> 0 | WM5: =WM4 -> 0 | WU5: =WU4 -> 0 | XC5: =XC4 -> 0 | XK5: =XK4 -> 0 | XS5: =XS4 -> 0 | YA5: =YA4 -> 0 | YI5: =YI4 -> 0 | YQ5: =YQ4 -> 0 | YY5: =YY4 -> 0 | ZG5: =ZG4 -> 0 | ZO5: =ZO4 -> 0 | ZW5: =ZW4 -> 0 | AAE5: =AAE4 -> 0 | AAM5: =AAM4 -> 0 | AAU5: =AAU4 -> 0 | ABC5: =ABC4 -> 0 | ABK5: =ABK4 -> 0 | ABS5: =ABS4 -> 0 | ACA5: =ACA4 -> 0
A6: FECHA | B6: PRESTAMOS | C6: ABONO | D6: NUEVO | E6: FECHA DE | F6: INTERSES | G6: INTERESES | I6: FECHA | J6: PRESTAMOS | K6: ABONO | L6: NUEVO | M6: FECHA DE | N6: INTERSES | O6: INTERESES | Q6: FECHA | R6: PRESTAMOS | S6: ABONO | T6: NUEVO | U6: FECHA DE | V6: INTERSES | W6: INTERESES | Y6: FECHA | Z6: PRESTAMOS | AA6: ABONO | AB6: NUEVO | AC6: FECHA DE | AD6: INTERSES | AE6: INTERESES | AG6: FECHA | AH6: PRESTAMOS | AI6: ABONO | AJ6: NUEVO | AK6: FECHA DE | AL6: INTERSES | AM6: INTERESES | AO6: FECHA | AP6: PRESTAMOS | AQ6: ABONO | AR6: NUEVO | AS6: FECHA DE | AT6: INTERSES | AU6: INTERESES | AW6: FECHA | AX6: PRESTAMOS | AY6: ABONO | AZ6: NUEVO | BA6: FECHA DE | BB6: INTERSES | BC6: INTERESES | BE6: FECHA | BF6: PRESTAMOS | BG6: ABONO | BH6: NUEVO | BI6: FECHA DE | BJ6: INTERSES | BK6: INTERESES | BM6: FECHA | BN6: PRESTAMOS | BO6: ABONO | BP6: NUEVO | BQ6: FECHA DE | BR6: INTERSES | BS6: INTERESES | BU6: FECHA | BV6: PRESTAMOS | BW6: ABONO | BX6: NUEVO | BY6: FECHA DE | BZ6: INTERSES | CA6: INTERESES | CC6: FECHA | CD6: PRESTAMOS | CE6: ABONO | CF6: NUEVO | CG6: FECHA DE | CH6: INTERSES | CI6: INTERESES | CK6: FECHA | CL6: PRESTAMOS | CM6: ABONO | CN6: NUEVO | CO6: FECHA DE | CP6: INTERSES | CQ6: INTERESES | CS6: FECHA | CT6: PRESTAMOS | CU6: ABONO | CV6: NUEVO | CW6: FECHA DE | CX6: INTERSES | CY6: INTERESES | DA6: FECHA | DB6: PRESTAMOS | DC6: ABONO | DD6: NUEVO | DE6: FECHA DE | DF6: INTERSES | DG6: INTERESES | DI6: FECHA | DJ6: PRESTAMOS | DK6: ABONO | DL6: NUEVO | DM6: FECHA DE | DN6: INTERSES | DO6: INTERESES | DQ6: FECHA | DR6: PRESTAMOS | DS6: ABONO | DT6: NUEVO | DU6: FECHA DE | DV6: INTERSES | DW6: INTERESES | DY6: FECHA | DZ6: PRESTAMOS | EA6: ABONO | EB6: NUEVO | EC6: FECHA DE | ED6: INTERSES | EE6: INTERESES | EG6: FECHA | EH6: PRESTAMOS | EI6: ABONO | EJ6: NUEVO | EK6: FECHA DE | EL6: INTERSES | EM6: INTERESES | EO6: FECHA | EP6: PRESTAMOS | EQ6: ABONO | ER6: NUEVO | ES6: FECHA DE | ET6: INTERSES | EU6: INTERESES | EW6: FECHA | EX6: PRESTAMOS | EY6: ABONO | EZ6: NUEVO | FA6: FECHA DE | FB6: INTERSES | FC6: INTERESES | FE6: FECHA | FF6: PRESTAMOS | FG6: ABONO | FH6: NUEVO | FI6: FECHA DE | FJ6: INTERSES | FK6: INTERESES | FM6: FECHA | FN6: PRESTAMOS | FO6: ABONO | FP6: NUEVO | FQ6: FECHA DE | FR6: INTERSES | FS6: INTERESES | FU6: FECHA | FV6: PRESTAMOS | FW6: ABONO | FX6: NUEVO | FY6: FECHA DE | FZ6: INTERSES | GA6: INTERESES | GC6: FECHA | GD6: PRESTAMOS | GE6: ABONO | GF6: NUEVO | GG6: FECHA DE | GH6: INTERSES | GI6: INTERESES | GK6: FECHA | GL6: PRESTAMOS | GM6: ABONO | GN6: NUEVO | GO6: FECHA DE | GP6: INTERSES | GQ6: INTERESES | GS6: FECHA | GT6: PRESTAMOS | GU6: ABONO | GV6: NUEVO | GW6: FECHA DE | GX6: INTERSES | GY6: INTERESES | HA6: FECHA | HB6: PRESTAMOS | HC6: ABONO | HD6: NUEVO | HE6: FECHA DE | HF6: INTERSES | HG6: INTERESES | HI6: FECHA | HJ6: PRESTAMOS | HK6: ABONO | HL6: NUEVO | HM6: FECHA DE | HN6: INTERSES | HO6: INTERESES | HQ6: FECHA | HR6: PRESTAMOS | HS6: ABONO | HT6: NUEVO | HU6: FECHA DE | HV6: INTERSES | HW6: INTERESES | HY6: FECHA | HZ6: PRESTAMOS | IA6: ABONO | IB6: NUEVO | IC6: FECHA DE | ID6: INTERSES | IE6: INTERESES | IG6: FECHA | IH6: PRESTAMOS | II6: ABONO | IJ6: NUEVO | IK6: FECHA DE | IL6: INTERSES | IM6: INTERESES | IO6: FECHA | IP6: PRESTAMOS | IQ6: ABONO | IR6: NUEVO | IS6: FECHA DE | IT6: INTERSES | IU6: INTERESES | IW6: FECHA | IX6: PRESTAMOS | IY6: ABONO | IZ6: NUEVO | JA6: FECHA DE | JB6: INTERSES | JC6: INTERESES | JE6: FECHA | JF6: PRESTAMOS | JG6: ABONO | JH6: NUEVO | JI6: FECHA DE | JJ6: INTERSES | JK6: INTERESES | JM6: FECHA | JN6: PRESTAMOS | JO6: ABONO | JP6: NUEVO | JQ6: FECHA DE | JR6: INTERSES | JS6: INTERESES | JU6: FECHA | JV6: PRESTAMOS | JW6: ABONO | JX6: NUEVO | JY6: FECHA DE | JZ6: INTERSES | KA6: INTERESES | KC6: FECHA | KD6: PRESTAMOS | KE6: ABONO | KF6: NUEVO | KG6: FECHA DE | KH6: INTERSES | KI6: INTERESES | KK6: FECHA | KL6: PRESTAMOS | KM6: ABONO | KN6: NUEVO | KO6: FECHA DE | KP6: INTERSES | KQ6: INTERESES | KS6: FECHA | KT6: PRESTAMOS | KU6: ABONO | KV6: NUEVO | KW6: FECHA DE | KX6: INTERSES | KY6: INTERESES | LA6: FECHA | LB6: PRESTAMOS | LC6: ABONO | LD6: NUEVO | LE6: FECHA DE | LF6: INTERSES | LG6: INTERESES | LI6: FECHA | LJ6: PRESTAMOS | LK6: ABONO | LL6: NUEVO | LM6: FECHA DE | LN6: INTERSES | LO6: INTERESES | LQ6: FECHA | LR6: PRESTAMOS | LS6: ABONO | LT6: NUEVO | LU6: FECHA DE | LV6: INTERSES | LW6: INTERESES | LY6: FECHA | LZ6: PRESTAMOS | MA6: ABONO | MB6: NUEVO | MC6: FECHA DE | MD6: INTERSES | ME6: INTERESES | MG6: FECHA | MH6: PRESTAMOS | MI6: ABONO | MJ6: NUEVO | MK6: FECHA DE | ML6: INTERSES | MM6: INTERESES | MO6: FECHA | MP6: PRESTAMOS | MQ6: ABONO | MR6: NUEVO | MS6: FECHA DE | MT6: INTERSES | MU6: INTERESES | MW6: FECHA | MX6: PRESTAMOS | MY6: ABONO | MZ6: NUEVO | NA6: FECHA DE | NB6: INTERSES | NC6: INTERESES | NE6: FECHA | NF6: PRESTAMOS | NG6: ABONO | NH6: NUEVO | NI6: FECHA DE | NJ6: INTERSES | NK6: INTERESES | NM6: FECHA | NN6: PRESTAMOS | NO6: ABONO | NP6: NUEVO | NQ6: FECHA DE | NR6: INTERSES | NS6: INTERESES | NU6: FECHA | NV6: PRESTAMOS | NW6: ABONO | NX6: NUEVO | NY6: FECHA DE | NZ6: INTERSES | OA6: INTERESES | OC6: FECHA | OD6: PRESTAMOS | OE6: ABONO | OF6: NUEVO | OG6: FECHA DE | OH6: INTERSES | OI6: INTERESES | OK6: FECHA | OL6: PRESTAMOS | OM6: ABONO | ON6: NUEVO | OO6: FECHA DE | OP6: INTERSES | OQ6: INTERESES | OS6: FECHA | OT6: PRESTAMOS | OU6: ABONO | OV6: NUEVO | OW6: FECHA DE | OX6: INTERSES | OY6: INTERESES | PA6: FECHA | PB6: PRESTAMOS | PC6: ABONO | PD6: NUEVO | PE6: FECHA DE | PF6: INTERSES | PG6: INTERESES | PI6: FECHA | PJ6: PRESTAMOS | PK6: ABONO | PL6: NUEVO | PM6: FECHA DE | PN6: INTERSES | PO6: INTERESES | PQ6: FECHA | PR6: PRESTAMOS | PS6: ABONO | PT6: NUEVO | PU6: FECHA DE | PV6: INTERSES | PW6: INTERESES | PY6: FECHA | PZ6: PRESTAMOS | QA6: ABONO | QB6: NUEVO | QC6: FECHA DE | QD6: INTERSES | QE6: INTERESES | QG6: FECHA | QH6: PRESTAMOS | QI6: ABONO | QJ6: NUEVO | QK6: FECHA DE | QL6: INTERSES | QM6: INTERESES | QO6: FECHA | QP6: PRESTAMOS | QQ6: ABONO | QR6: NUEVO | QS6: FECHA DE | QT6: INTERSES | QU6: INTERESES | QW6: FECHA | QX6: PRESTAMOS | QY6: ABONO | QZ6: NUEVO | RA6: FECHA DE | RB6: INTERSES | RC6: INTERESES | RE6: FECHA | RF6: PRESTAMOS | RG6: ABONO | RH6: NUEVO | RI6: FECHA DE | RJ6: INTERSES | RK6: INTERESES | RM6: FECHA | RN6: PRESTAMOS | RO6: ABONO | RP6: NUEVO | RQ6: FECHA DE | RR6: INTERSES | RS6: INTERESES | RU6: FECHA | RV6: PRESTAMOS | RW6: ABONO | RX6: NUEVO | RY6: FECHA DE | RZ6: INTERSES | SA6: INTERESES | SC6: FECHA | SD6: PRESTAMOS | SE6: ABONO | SF6: NUEVO | SG6: FECHA DE | SH6: INTERSES | SI6: INTERESES | SK6: FECHA | SL6: PRESTAMOS | SM6: ABONO | SN6: NUEVO | SO6: FECHA DE | SP6: INTERSES | SQ6: INTERESES | SS6: FECHA | ST6: PRESTAMOS | SU6: ABONO | SV6: NUEVO | SW6: FECHA DE | SX6: INTERSES | SY6: INTERESES | TA6: FECHA | TB6: PRESTAMOS | TC6: ABONO | TD6: NUEVO | TE6: FECHA DE | TF6: INTERSES | TG6: INTERESES | TI6: FECHA | TJ6: PRESTAMOS | TK6: ABONO | TL6: NUEVO | TM6: FECHA DE | TN6: INTERSES | TO6: INTERESES | TQ6: FECHA | TR6: PRESTAMOS | TS6: ABONO | TT6: NUEVO | TU6: FECHA DE | TV6: INTERSES | TW6: INTERESES | TY6: FECHA | TZ6: PRESTAMOS | UA6: ABONO | UB6: NUEVO | UC6: FECHA DE | UD6: INTERSES | UE6: INTERESES | UG6: FECHA | UH6: PRESTAMOS | UI6: ABONO | UJ6: NUEVO | UK6: FECHA DE | UL6: INTERSES | UM6: INTERESES | UO6: FECHA | UP6: PRESTAMOS | UQ6: ABONO | UR6: NUEVO | US6: FECHA DE | UT6: INTERSES | UU6: INTERESES | UW6: FECHA | UX6: PRESTAMOS | UY6: ABONO | UZ6: NUEVO | VA6: FECHA DE | VB6: INTERSES | VC6: INTERESES | VE6: FECHA | VF6: PRESTAMOS | VG6: ABONO | VH6: NUEVO | VI6: FECHA DE | VJ6: INTERSES | VK6: INTERESES | VM6: FECHA | VN6: PRESTAMOS | VO6: ABONO | VP6: NUEVO | VQ6: FECHA DE | VR6: INTERSES | VS6: INTERESES | VU6: FECHA | VV6: PRESTAMOS | VW6: ABONO | VX6: NUEVO | VY6: FECHA DE | VZ6: INTERSES | WA6: INTERESES | WC6: FECHA | WD6: PRESTAMOS | WE6: ABONO | WF6: NUEVO | WG6: FECHA DE | WH6: INTERSES | WI6: INTERESES | WK6: FECHA | WL6: PRESTAMOS | WM6: ABONO | WN6: NUEVO | WO6: FECHA DE | WP6: INTERSES | WQ6: INTERESES | WS6: FECHA | WT6: PRESTAMOS | WU6: ABONO | WV6: NUEVO | WW6: FECHA DE | WX6: INTERSES | WY6: INTERESES | XA6: FECHA | XB6: PRESTAMOS | XC6: ABONO | XD6: NUEVO | XE6: FECHA DE | XF6: INTERSES | XG6: INTERESES | XI6: FECHA | XJ6: PRESTAMOS | XK6: ABONO | XL6: NUEVO | XM6: FECHA DE | XN6: INTERSES | XO6: INTERESES | XQ6: FECHA | XR6: PRESTAMOS | XS6: ABONO | XT6: NUEVO | XU6: FECHA DE | XV6: INTERSES | XW6: INTERESES | XY6: FECHA | XZ6: PRESTAMOS | YA6: ABONO | YB6: NUEVO | YC6: FECHA DE | YD6: INTERSES | YE6: INTERESES | YG6: FECHA | YH6: PRESTAMOS | YI6: ABONO | YJ6: NUEVO | YK6: FECHA DE | YL6: INTERSES | YM6: INTERESES | YO6: FECHA | YP6: PRESTAMOS | YQ6: ABONO | YR6: NUEVO | YS6: FECHA DE | YT6: INTERSES | YU6: INTERESES | YW6: FECHA | YX6: PRESTAMOS | YY6: ABONO | YZ6: NUEVO | ZA6: FECHA DE | ZB6: INTERSES | ZC6: INTERESES | ZE6: FECHA | ZF6: PRESTAMOS | ZG6: ABONO | ZH6: NUEVO | ZI6: FECHA DE | ZJ6: INTERSES | ZK6: INTERESES | ZM6: FECHA | ZN6: PRESTAMOS | ZO6: ABONO | ZP6: NUEVO | ZQ6: FECHA DE | ZR6: INTERSES | ZS6: INTERESES | ZU6: FECHA | ZV6: PRESTAMOS | ZW6: ABONO | ZX6: NUEVO | ZY6: FECHA DE | ZZ6: INTERSES | AAA6: INTERESES | AAC6: FECHA | AAD6: PRESTAMOS | AAE6: ABONO | AAF6: NUEVO | AAG6: FECHA DE | AAH6: INTERSES | AAI6: INTERESES | AAK6: FECHA | AAL6: PRESTAMOS | AAM6: ABONO | AAN6: NUEVO | AAO6: FECHA DE | AAP6: INTERSES | AAQ6: INTERESES | AAS6: FECHA | AAT6: PRESTAMOS | AAU6: ABONO | AAV6: NUEVO | AAW6: FECHA DE | AAX6: INTERSES | AAY6: INTERESES | ABA6: FECHA | ABB6: PRESTAMOS | ABC6: ABONO | ABD6: NUEVO | ABE6: FECHA DE | ABF6: INTERSES | ABG6: INTERESES | ABI6: FECHA | ABJ6: PRESTAMOS | ABK6: ABONO | ABL6: NUEVO | ABM6: FECHA DE | ABN6: INTERSES | ABO6: INTERESES | ABQ6: FECHA | ABR6: PRESTAMOS | ABS6: ABONO | ABT6: NUEVO | ABU6: FECHA DE | ABV6: INTERSES | ABW6: INTERESES | ABY6: FECHA | ABZ6: PRESTAMOS | ACA6: ABONO | ACB6: NUEVO | ACC6: FECHA DE | ACD6: INTERSES | ACE6: INTERESES
B7: CONCEDIDO | D7: SALDO | E7: INTERES | F7: PAGADOS | G7: PENDIENTES | J7: CONCEDIDO | L7: SALDO | M7: INTERES | N7: PAGADOS | O7: PENDIENTES | R7: CONCEDIDO | T7: SALDO | U7: INTERES | V7: PAGADOS | W7: PENDIENTES | Z7: CONCEDIDO | AB7: SALDO | AC7: INTERES | AE7: PENDIENTES | AH7: CONCEDIDO | AJ7: SALDO | AK7: INTERES | AL7: PAGADOS | AM7: PENDIENTES | AP7: CONCEDIDO | AR7: SALDO | AS7: INTERES | AT7: PAGADOS | AU7: PENDIENTES | AX7: CONCEDIDO | AZ7: SALDO | BA7: INTERES | BB7: PAGADOS | BC7: PENDIENTES | BF7: CONCEDIDO | BH7: SALDO | BI7: INTERES | BJ7: PAGADOS | BK7: PENDIENTES | BN7: CONCEDIDO | BP7: SALDO | BQ7: INTERES | BR7: PAGADOS | BS7: PENDIENTES | BV7: CONCEDIDO | BX7: SALDO | BY7: INTERES | BZ7: PAGADOS | CA7: PENDIENTES | CD7: CONCEDIDO | CF7: SALDO | CG7: INTERES | CH7: PAGADOS | CI7: PENDIENTES | CL7: CONCEDIDO | CN7: SALDO | CO7: INTERES | CP7: PAGADOS | CQ7: PENDIENTES | CT7: CONCEDIDO | CV7: SALDO | CW7: INTERES | CX7: PAGADOS | CY7: PENDIENTES | DB7: CONCEDIDO | DD7: SALDO | DE7: INTERES | DF7: PAGADOS | DG7: PENDIENTES | DJ7: CONCEDIDO | DL7: SALDO | DM7: INTERES | DN7: PAGADOS | DO7: PENDIENTES | DR7: CONCEDIDO | DT7: SALDO | DU7: INTERES | DV7: PAGADOS | DW7: PENDIENTES | DZ7: CONCEDIDO | EB7: SALDO | EC7: INTERES | ED7: PAGADOS | EE7: PENDIENTES | EH7: CONCEDIDO | EJ7: SALDO | EK7: INTERES | EL7: PAGADOS | EM7: PENDIENTES | EP7: CONCEDIDO | ER7: SALDO | ES7: INTERES | ET7: PAGADOS | EU7: PENDIENTES | EX7: CONCEDIDO | EZ7: SALDO | FA7: INTERES | FB7: PAGADOS | FC7: PENDIENTES | FF7: CONCEDIDO | FH7: SALDO | FI7: INTERES | FJ7: PAGADOS | FK7: PENDIENTES | FN7: CONCEDIDO | FP7: SALDO | FQ7: INTERES | FR7: PAGADOS | FS7: PENDIENTES | FV7: CONCEDIDO | FX7: SALDO | FY7: INTERES | FZ7: PAGADOS | GA7: PENDIENTES | GD7: CONCEDIDO | GF7: SALDO | GG7: INTERES | GH7: PAGADOS | GI7: PENDIENTES | GL7: CONCEDIDO | GN7: SALDO | GO7: INTERES | GP7: PAGADOS | GQ7: PENDIENTES | GT7: CONCEDIDO | GV7: SALDO | GW7: INTERES | GX7: PAGADOS | HB7: CONCEDIDO | HD7: SALDO | HE7: INTERES | HF7: PAGADOS | HG7: PENDIENTES | HJ7: CONCEDIDO | HL7: SALDO | HM7: INTERES | HN7: PAGADOS | HO7: PENDIENTES | HR7: CONCEDIDO | HT7: SALDO | HU7: INTERES | HV7: PAGADOS | HW7: PENDIENTES | HZ7: CONCEDIDO | IB7: SALDO | IC7: INTERES | ID7: PAGADOS | IE7: PENDIENTES | IH7: CONCEDIDO | IJ7: SALDO | IK7: INTERES | IP7: CONCEDIDO | IR7: SALDO | IS7: INTERES | IT7: PAGADOS | IU7: PENDIENTES | IX7: CONCEDIDO | IZ7: SALDO | JA7: INTERES | JB7: PAGADOS | JC7: PENDIENTES | JF7: CONCEDIDO | JH7: SALDO | JI7: INTERES | JJ7: PAGADOS | JK7: PENDIENTES | JN7: CONCEDIDO | JP7: SALDO | JQ7: INTERES | JR7: PAGADOS | JS7: PENDIENTES | JV7: CONCEDIDO | JX7: SALDO | JY7: INTERES | JZ7: PAGADOS | KA7: PENDIENTES | KD7: CONCEDIDO | KF7: SALDO | KG7: INTERES | KH7: PAGADOS | KI7: PENDIENTES | KL7: CONCEDIDO | KN7: SALDO | KO7: INTERES | KP7: PAGADOS | KQ7: PENDIENTES | KT7: CONCEDIDO | KV7: SALDO | KW7: INTERES | KX7: PAGADOS | KY7: PENDIENTES | LB7: CONCEDIDO | LD7: SALDO | LE7: INTERES | LF7: PAGADOS | LG7: PENDIENTES | LL7: SALDO | LM7: INTERES | LN7: PAGADOS | LO7: PENDIENTES | LR7: CONCEDIDO | LT7: SALDO | LU7: INTERES | LV7: PAGADOS | LW7: PENDIENTES | LZ7: CONCEDIDO | MB7: SALDO | MC7: INTERES | MD7: PAGADOS | ME7: PENDIENTES | MH7: CONCEDIDO | MJ7: SALDO | MK7: INTERES | ML7: PAGADOS | MM7: PENDIENTES | MP7: CONCEDIDO | MR7: SALDO | MS7: INTERES | MT7: PAGADOS | MU7: PENDIENTES | MX7: CONCEDIDO | MZ7: SALDO | NA7: INTERES | NB7: PAGADOS | NC7: PENDIENTES | NF7: CONCEDIDO | NH7: SALDO | NI7: INTERES | NJ7: PAGADOS | NK7: PENDIENTES | NN7: CONCEDIDO | NP7: SALDO | NQ7: INTERES | NR7: PAGADOS | NS7: PENDIENTES | NV7: CONCEDIDO | NX7: SALDO | NY7: INTERES | NZ7: PAGADOS | OA7: PENDIENTES | OD7: CONCEDIDO | OF7: SALDO | OG7: INTERES | OH7: PAGADOS | OI7: PENDIENTES | OL7: CONCEDIDO | ON7: SALDO | OO7: INTERES | OP7: PAGADOS | OQ7: PENDIENTES | OT7: CONCEDIDO | OV7: SALDO | OW7: INTERES | OX7: PAGADOS | OY7: PENDIENTES | PB7: CONCEDIDO | PD7: SALDO | PE7: INTERES | PF7: PAGADOS | PG7: PENDIENTES | PJ7: CONCEDIDO | PL7: SALDO | PM7: INTERES | PN7: PAGADOS | PO7: PENDIENTES | PR7: CONCEDIDO | PT7: SALDO | PU7: INTERES | PV7: PAGADOS | PW7: PENDIENTES | PZ7: CONCEDIDO | QB7: SALDO | QC7: INTERES | QD7: PAGADOS | QE7: PENDIENTES | QH7: CONCEDIDO | QJ7: SALDO | QK7: INTERES | QL7: PAGADOS | QM7: PENDIENTES | QP7: CONCEDIDO | QR7: SALDO | QS7: INTERES | QT7: PAGADOS | QU7: PENDIENTES | QX7: CONCEDIDO | QZ7: SALDO | RA7: INTERES | RB7: PAGADOS | RC7: PENDIENTES | RF7: CONCEDIDO | RH7: SALDO | RI7: INTERES | RJ7: PAGADOS | RK7: PENDIENTES | RN7: CONCEDIDO | RP7: SALDO | RQ7: INTERES | RR7: PAGADOS | RS7: PENDIENTES | RV7: CONCEDIDO | RX7: SALDO | RY7: INTERES | RZ7: PAGADOS | SA7: PENDIENTES | SD7: CONCEDIDO | SF7: SALDO | SG7: INTERES | SH7: PAGADOS | SI7: PENDIENTES | SL7: CONCEDIDO | SN7: SALDO | SO7: INTERES | SP7: PAGADOS | SQ7: PENDIENTES | ST7: CONCEDIDO | SV7: SALDO | SW7: INTERES | SX7: PAGADOS | SY7: PENDIENTES | TB7: CONCEDIDO | TD7: SALDO | TE7: INTERES | TF7: PAGADOS | TG7: PENDIENTES | TJ7: CONCEDIDO | TL7: SALDO | TM7: INTERES | TN7: PAGADOS | TO7: PENDIENTES | TR7: CONCEDIDO | TT7: SALDO | TU7: INTERES | TV7: PAGADOS | TW7: PENDIENTES | TZ7: CONCEDIDO | UB7: SALDO | UC7: INTERES | UD7: PAGADOS | UE7: PENDIENTES | UH7: CONCEDIDO | UJ7: SALDO | UK7: INTERES | UL7: PAGADOS | UM7: PENDIENTES | UP7: CONCEDIDO | UR7: SALDO | US7: INTERES | UT7: PAGADOS | UU7: PENDIENTES | UX7: CONCEDIDO | UZ7: SALDO | VA7: INTERES | VB7: PAGADOS | VC7: PENDIENTES | VF7: CONCEDIDO | VH7: SALDO | VI7: INTERES | VJ7: PAGADOS | VK7: PENDIENTES | VN7: CONCEDIDO | VP7: SALDO | VQ7: INTERES | VR7: PAGADOS | VS7: PENDIENTES | VV7: CONCEDIDO | VX7: SALDO | VY7: INTERES | VZ7: PAGADOS | WA7: PENDIENTES | WD7: CONCEDIDO | WF7: SALDO | WG7: INTERES | WH7: PAGADOS | WI7: PENDIENTES | WL7: CONCEDIDO | WN7: ? | WO7: INTERES | WP7: PAGADOS | WQ7: PENDIENTES | WT7: CONCEDIDO | WV7: SALDO | WW7: INTERES | WX7: PAGADOS | WY7: PENDIENTES | XB7: CONCEDIDO | XD7: SALDO | XE7: INTERES | XF7: PAGADOS | XG7: PENDIENTES | XJ7: CONCEDIDO | XL7: SALDO | XM7: INTERES | XN7: PAGADOS | XO7: PENDIENTES | XR7: CONCEDIDO | XT7: SALDO | XU7: INTERES | XV7: PAGADOS | XW7: PENDIENTES | XZ7: CONCEDIDO | YB7: SALDO | YC7: INTERES | YD7: PAGADOS | YE7: PENDIENTES | YH7: CONCEDIDO | YJ7: SALDO | YK7: INTERES | YL7: PAGADOS | YM7: PENDIENTES | YP7: CONCEDIDO | YR7: SALDO | YS7: INTERES | YT7: PAGADOS | YU7: PENDIENTES | YX7: CONCEDIDO | YZ7: SALDO | ZA7: INTERES | ZB7: PAGADOS | ZC7: PENDIENTES | ZF7: CONCEDIDO | ZH7: SALDO | ZI7: INTERES | ZJ7: PAGADOS | ZK7: PENDIENTES | ZN7: CONCEDIDO | ZP7: SALDO | ZQ7: INTERES | ZR7: PAGADOS | ZS7: PENDIENTES | ZV7: CONCEDIDO | ZX7: SALDO | ZY7: INTERES | ZZ7: PAGADOS | AAA7: PENDIENTES | AAD7: CONCEDIDO | AAF7: SALDO | AAG7: INTERES | AAH7: PAGADOS | AAI7: PENDIENTES | AAL7: CONCEDIDO | AAN7: SALDO | AAO7: INTERES | AAP7: PAGADOS | AAQ7: PENDIENTES | AAT7: CONCEDIDO | AAV7: SALDO | AAW7: INTERES | AAX7: PAGADOS | AAY7: PENDIENTES | ABB7: CONCEDIDO | ABD7: SALDO | ABE7: INTERES | ABF7: PAGADOS | ABG7: PENDIENTES | ABJ7: CONCEDIDO | ABL7: SALDO | ABM7: INTERES | ABN7: PAGADOS | ABO7: PENDIENTES | ABR7: CONCEDIDO | ABT7: SALDO | ABU7: INTERES | ABV7: PAGADOS | ABW7: PENDIENTES | ABZ7: CONCEDIDO | ACB7: SALDO | ACC7: INTERES | ACD7: PAGADOS | ACE7: PENDIENTES
A8: 46023 | B8: 2000 | D8: =B8 -> 2000 | E8: 46021 | I8: 46023 | J8: 800 | L8: =J8 -> 800 | M8: 46021 | Q8: 46023 | R8: 4200 | T8: =R8 -> 4200 | U8: 46021 | Y8: 46023 | Z8: 1000 | AB8: =Z8 -> 1000 | AC8: 46021 | AG8: 46023 | AH8: 1000 | AJ8: =AH8 -> 1000 | AK8: 46021 | AO8: 46023 | AP8: 1000 | AR8: =AP8 -> 1000 | AS8: 46021 | AW8: 46023 | AX8: 1200 | AZ8: =AX8 -> 1200 | BA8: 46021 | BE8: 46023 | BF8: 5000 | BH8: =BF8 -> 5000 | BI8: 46021 | BM8: 46023 | BN8: 1000 | BP8: =BN8 -> 1000 | BQ8: 46021 | BU8: 46023 | BV8: 1500 | BX8: =BV8 -> 1500 | BY8: 46021 | CF8: =CD8 -> 0 | CG8: 46037 | CN8: =CL8 -> 0 | CO8: 46037 | CV8: =CT8 -> 0 | CW8: 46037 | DD8: =DB8 -> 0 | DE8: 46037 | DL8: =DJ8 -> 0 | DM8: 46021 | DT8: =DR8 -> 0 | DU8: 46021 | EB8: =DZ8 -> 0 | EC8: 46021 | EJ8: =EH8 -> 0 | EK8: 46021 | ER8: =EP8 -> 0 | ES8: 46021 | ET8: 0 | EZ8: =EX8 -> 0 | FA8: 46021 | FB8: 0 | FH8: =FF8 -> 0 | FI8: 46021 | FJ8: 0 | FK8: 0 | FP8: =FN8 -> 0 | FQ8: 46021 | FR8: 0 | FX8: =FV8 -> 0 | FY8: 46021 | FZ8: 0 | GA8: 0 | GF8: =GD8 -> 0 | GG8: 46021 | GN8: =GL8 -> 0 | GO8: 46037 | GV8: =GT8 -> 0 | GW8: 46037 | HD8: =HB8 -> 0 | HE8: 46037 | HL8: =HJ8 -> 0 | HM8: 46037 | HT8: =HR8 -> 0 | HU8: 46037 | IB8: =HZ8 -> 0 | IC8: 46037 | IJ8: =IH8 -> 0 | IK8: 46037 | IR8: =IP8 -> 0 | IS8: 46037 | IZ8: =IX8 -> 0 | JA8: 46037 | JH8: =JF8 -> 0 | JI8: 46037 | JP8: =JN8 -> 0 | JQ8: 46037 | JX8: =JV8 -> 0 | JY8: 46037 | KF8: =KD8 -> 0 | KG8: 46037 | KN8: =KL8 -> 0 | KO8: 46037 | KV8: =KT8 -> 0 | KW8: 46037 | LD8: =LB8 -> 0 | LE8: 46037 | LL8: =LJ8 -> 0 | LM8: 46037 | LT8: =LR8 -> 0 | LU8: 46037 | MB8: =LZ8 -> 0 | MC8: 46037 | MJ8: =MH8 -> 0 | MK8: 46037 | MR8: =MP8 -> 0 | MS8: 46037 | MZ8: =MX8 -> 0 | NA8: 46037 | NH8: =NF8 -> 0 | NI8: 46037 | NP8: =NN8 -> 0 | NQ8: 46037 | NX8: =NV8 -> 0 | NY8: 46037 | OF8: =OD8 -> 0 | OG8: 46037 | ON8: =OL8 -> 0 | OO8: 46037 | OV8: =OT8 -> 0 | OW8: 46037 | PD8: =PB8 -> 0 | PE8: 46037 | PL8: =PJ8 -> 0 | PM8: 46037 | PT8: =PR8 -> 0 | PU8: 46037 | QB8: =PZ8 -> 0 | QC8: 46037 | QJ8: =QH8 -> 0 | QK8: 46037 | QR8: =QP8 -> 0 | QS8: 46037 | QZ8: =QX8 -> 0 | RA8: 46037 | RH8: =RF8 -> 0 | RI8: 46037 | RP8: =RN8 -> 0 | RQ8: 46037 | RX8: =RV8 -> 0 | RY8: 46037 | SF8: =SD8 -> 0 | SG8: 46037 | SN8: =SL8 -> 0 | SO8: 46037 | SV8: =ST8 -> 0 | SW8: 46037 | TD8: =TB8 -> 0 | TE8: 46037 | TL8: =TJ8 -> 0 | TM8: 46037 | TT8: =TR8 -> 0 | TU8: 46037 | UB8: =TZ8 -> 0 | UC8: 46037 | UJ8: =UH8 -> 0 | UK8: 46037 | UR8: =UP8 -> 0 | US8: 46037 | UZ8: =UX8 -> 0 | VA8: 46037 | VH8: =VF8 -> 0 | VI8: 46037 | VP8: =VN8 -> 0 | VQ8: 46037 | VX8: =VV8 -> 0 | VY8: 46037 | WF8: =WD8 -> 0 | WG8: 46037 | WN8: =WL8 -> 0 | WO8: 46037 | WV8: =WT8 -> 0 | WW8: 46037 | XD8: =XB8 -> 0 | XE8: 46037 | XL8: =XJ8 -> 0 | XM8: 46037 | XT8: =XR8 -> 0 | XU8: 46037 | YB8: =XZ8 -> 0 | YC8: 46037 | YJ8: =YH8 -> 0 | YK8: 46037 | YR8: =YP8 -> 0 | YS8: 46037 | YZ8: =YX8 -> 0 | ZA8: 46037 | ZH8: =ZF8 -> 0 | ZI8: 46037 | ZP8: =ZN8 -> 0 | ZQ8: 46037 | ZX8: =ZV8 -> 0 | ZY8: 46037 | AAF8: =AAD8 -> 0 | AAG8: 46037 | AAN8: =AAL8 -> 0 | AAO8: 46037 | AAV8: =AAT8 -> 0 | AAW8: 46037 | ABD8: =ABB8 -> 0 | ABE8: 46037 | ABL8: =ABJ8 -> 0 | ABM8: 46037 | ABT8: =ABR8 -> 0 | ABU8: 46037 | ACB8: =ABZ8 -> 0 | ACC8: 46037
A9: 46037 | C9: 300 | D9: =SUM(D8,B9,-C9) -> 1700 | E9: 46037 | F9: 100 | I9: 46037 | J9: 200 | L9: =SUM(L8,J9,-K9) -> 1000 | M9: 46037 | N9: 24 | Q9: 46037 | S9: 200 | T9: =SUM(T8,R9,-S9) -> 4000 | U9: 46037 | V9: 84 | Y9: 46037 | AB9: =SUM(AB8,Z9,-AA9) -> 1000 | AC9: 46037 | AE9: 40 | AG9: 46037 | AH9: 1000 | AJ9: =SUM(AJ8,AH9,-AI9) -> 2000 | AK9: 46037 | AL9: 40 | AO9: 46037 | AP9: 0 | AQ9: 0 | AR9: =SUM(AR8,AP9,-AQ9) -> 1000 | AS9: 46037 | AU9: 35 | AW9: 46037 | AY9: 50 | AZ9: =SUM(AZ8,AX9,-AY9) -> 1150 | BA9: 46037 | BB9: 42 | BE9: 46037 | BF9: 2000 | BH9: =SUM(BH8,BF9,-BG9) -> 7000 | BI9: 46037 | BJ9: 225 | BM9: 46037 | BN9: 0 | BO9: 0 | BP9: =SUM(BP8,BN9,-BO9) -> 1000 | BQ9: 46037 | BS9: 45 | BU9: 46037 | BW9: 1500 | BX9: =SUM(BX8,BV9,-BW9) -> 0 | BY9: 46037 | BZ9: 75 | CF9: =SUM(CF8,CD9,-CE9) -> 0 | CG9: 46052 | CN9: =SUM(CN8,CL9,-CM9) -> 0 | CO9: 46052 | CV9: =SUM(CV8,CT9,-CU9) -> 0 | CW9: 46052 | DD9: =SUM(DD8,DB9,-DC9) -> 0 | DE9: 46052 | DL9: =SUM(DL8,DJ9,-DK9) -> 0 | DM9: 46037 | DT9: =SUM(DT8,DR9,-DS9) -> 0 | DU9: 46037 | EB9: =SUM(EB8,DZ9,-EA9) -> 0 | EC9: 46037 | EJ9: =SUM(EJ8,EH9,-EI9) -> 0 | EK9: 46037 | ER9: =SUM(ER8,EP9,-EQ9) -> 0 | ES9: 46037 | EZ9: =SUM(EZ8,EX9,-EY9) -> 0 | FA9: 46037 | FH9: =SUM(FH8,FF9,-FG9) -> 0 | FI9: 46037 | FP9: =SUM(FP8,FN9,-FO9) -> 0 | FQ9: 46037 | FX9: =SUM(FX8,FV9,-FW9) -> 0 | FY9: 46037 | GF9: =SUM(GF8,GD9,-GE9) -> 0 | GG9: 46037 | GH9: 0 | GN9: =SUM(GN8,GL9,-GM9) -> 0 | GO9: 46052 | GV9: =SUM(GV8,GT9,-GU9) -> 0 | GW9: 46052 | HD9: =SUM(HD8,HB9,-HC9) -> 0 | HE9: 46052 | HL9: =SUM(HL8,HJ9,-HK9) -> 0 | HM9: 46052 | HT9: =SUM(HT8,HR9,-HS9) -> 0 | HU9: 46052 | IB9: =SUM(IB8,HZ9,-IA9) -> 0 | IC9: 46052 | IJ9: =SUM(IJ8,IH9,-II9) -> 0 | IK9: 46052 | IR9: =SUM(IR8,IP9,-IQ9) -> 0 | IS9: 46052 | IZ9: =SUM(IZ8,IX9,-IY9) -> 0 | JA9: 46052 | JH9: =SUM(JH8,JF9,-JG9) -> 0 | JI9: 46052 | JP9: =SUM(JP8,JN9,-JO9) -> 0 | JQ9: 46052 | JX9: =SUM(JX8,JV9,-JW9) -> 0 | JY9: 46052 | KF9: =SUM(KF8,KD9,-KE9) -> 0 | KG9: 46052 | KN9: =SUM(KN8,KL9,-KM9) -> 0 | KO9: 46052 | KV9: =SUM(KV8,KT9,-KU9) -> 0 | KW9: 46052 | LD9: =SUM(LD8,LB9,-LC9) -> 0 | LE9: 46052 | LL9: =SUM(LL8,LJ9,-LK9) -> 0 | LM9: 46052 | LT9: =SUM(LT8,LR9,-LS9) -> 0 | LU9: 46052 | MB9: =SUM(MB8,LZ9,-MA9) -> 0 | MC9: 46052 | MJ9: =SUM(MJ8,MH9,-MI9) -> 0 | MK9: 46052 | MR9: =SUM(MR8,MP9,-MQ9) -> 0 | MS9: 46052 | MZ9: =SUM(MZ8,MX9,-MY9) -> 0 | NA9: 46052 | NH9: =SUM(NH8,NF9,-NG9) -> 0 | NI9: 46052 | NP9: =SUM(NP8,NN9,-NO9) -> 0 | NQ9: 46052 | NX9: =SUM(NX8,NV9,-NW9) -> 0 | NY9: 46052 | OF9: =SUM(OF8,OD9,-OE9) -> 0 | OG9: 46052 | ON9: =SUM(ON8,OL9,-OM9) -> 0 | OO9: 46052 | OV9: =SUM(OV8,OT9,-OU9) -> 0 | OW9: 46052 | PD9: =SUM(PD8,PB9,-PC9) -> 0 | PE9: 46052 | PL9: =SUM(PL8,PJ9,-PK9) -> 0 | PM9: 46052 | PT9: =SUM(PT8,PR9,-PS9) -> 0 | PU9: 46052 | QB9: =SUM(QB8,PZ9,-QA9) -> 0 | QC9: 46052 | QJ9: =SUM(QJ8,QH9,-QI9) -> 0 | QK9: 46052 | QR9: =SUM(QR8,QP9,-QQ9) -> 0 | QS9: 46052 | QZ9: =SUM(QZ8,QX9,-QY9) -> 0 | RA9: 46052 | RH9: =SUM(RH8,RF9,-RG9) -> 0 | RI9: 46052 | RP9: =SUM(RP8,RN9,-RO9) -> 0 | RQ9: 46052 | RX9: =SUM(RX8,RV9,-RW9) -> 0 | RY9: 46052 | SF9: =SUM(SF8,SD9,-SE9) -> 0 | SG9: 46052 | SN9: =SUM(SN8,SL9,-SM9) -> 0 | SO9: 46052 | SV9: =SUM(SV8,ST9,-SU9) -> 0 | SW9: 46052 | TD9: =SUM(TD8,TB9,-TC9) -> 0 | TE9: 46052 | TL9: =SUM(TL8,TJ9,-TK9) -> 0 | TM9: 46052 | TT9: =SUM(TT8,TR9,-TS9) -> 0 | TU9: 46052 | UB9: =SUM(UB8,TZ9,-UA9) -> 0 | UC9: 46052 | UJ9: =SUM(UJ8,UH9,-UI9) -> 0 | UK9: 46052 | UR9: =SUM(UR8,UP9,-UQ9) -> 0 | US9: 46052 | UZ9: =SUM(UZ8,UX9,-UY9) -> 0 | VA9: 46052 | VH9: =SUM(VH8,VF9,-VG9) -> 0 | VI9: 46052 | VP9: =SUM(VP8,VN9,-VO9) -> 0 | VQ9: 46052 | VX9: =SUM(VX8,VV9,-VW9) -> 0 | VY9: 46052 | WF9: =SUM(WF8,WD9,-WE9) -> 0 | WG9: 46052 | WN9: =SUM(WN8,WL9,-WM9) -> 0 | WO9: 46052 | WV9: =SUM(WV8,WT9,-WU9) -> 0 | WW9: 46052 | XD9: =SUM(XD8,XB9,-XC9) -> 0 | XE9: 46052 | XL9: =SUM(XL8,XJ9,-XK9) -> 0 | XM9: 46052 | XT9: =SUM(XT8,XR9,-XS9) -> 0 | XU9: 46052 | YB9: =SUM(YB8,XZ9,-YA9) -> 0 | YC9: 46052 | YJ9: =SUM(YJ8,YH9,-YI9) -> 0 | YK9: 46052 | YR9: =SUM(YR8,YP9,-YQ9) -> 0 | YS9: 46052 | YZ9: =SUM(YZ8,YX9,-YY9) -> 0 | ZA9: 46052 | ZH9: =SUM(ZH8,ZF9,-ZG9) -> 0 | ZI9: 46052 | ZP9: =SUM(ZP8,ZN9,-ZO9) -> 0 | ZQ9: 46052 | ZX9: =SUM(ZX8,ZV9,-ZW9) -> 0 | ZY9: 46052 | AAF9: =SUM(AAF8,AAD9,-AAE9) -> 0 | AAG9: 46052 | AAN9: =SUM(AAN8,AAL9,-AAM9) -> 0 | AAO9: 46052 | AAV9: =SUM(AAV8,AAT9,-AAU9) -> 0 | AAW9: 46052 | ABD9: =SUM(ABD8,ABB9,-ABC9) -> 0 | ABE9: 46052 | ABL9: =SUM(ABL8,ABJ9,-ABK9) -> 0 | ABM9: 46052 | ABT9: =SUM(ABT8,ABR9,-ABS9) -> 0 | ABU9: 46052 | ACB9: =SUM(ACB8,ABZ9,-ACA9) -> 0 | ACC9: 46052
D10: =SUM(D9,B10,-C10) -> 1700 | E10: 46052 | L10: =SUM(L9,J10,-K10) -> 1000 | M10: 46052 | T10: =SUM(T9,R10,-S10) -> 4000 | U10: 46052 | AB10: =SUM(AB9,Z10,-AA10) -> 1000 | AC10: 46052 | AJ10: =SUM(AJ9,AH10,-AI10) -> 2000 | AK10: 46052 | AR10: =SUM(AR9,AP10,-AQ10) -> 1000 | AS10: 46052 | AZ10: =SUM(AZ9,AX10,-AY10) -> 1150 | BA10: 46052 | BH10: =SUM(BH9,BF10,-BG10) -> 7000 | BI10: 46052 | BP10: =SUM(BP9,BN10,-BO10) -> 1000 | BQ10: 46052 | BX10: =SUM(BX9,BV10,-BW10) -> 0 | BY10: 46052 | CF10: =SUM(CF9,CD10,-CE10) -> 0 | CG10: 46068 | CN10: =SUM(CN9,CL10,-CM10) -> 0 | CO10: 46068 | CV10: =SUM(CV9,CT10,-CU10) -> 0 | CW10: 46068 | DD10: =SUM(DD9,DB10,-DC10) -> 0 | DE10: 46068 | DL10: =SUM(DL9,DJ10,-DK10) -> 0 | DM10: 46052 | DT10: =SUM(DT9,DR10,-DS10) -> 0 | DU10: 46052 | EB10: =SUM(EB9,DZ10,-EA10) -> 0 | EC10: 46052 | EJ10: =SUM(EJ9,EH10,-EI10) -> 0 | EK10: 46052 | ER10: =SUM(ER9,EP10,-EQ10) -> 0 | ES10: 46052 | EZ10: =SUM(EZ9,EX10,-EY10) -> 0 | FA10: 46052 | FH10: =SUM(FH9,FF10,-FG10) -> 0 | FI10: 46052 | FP10: =SUM(FP9,FN10,-FO10) -> 0 | FQ10: 46052 | FX10: =SUM(FX9,FV10,-FW10) -> 0 | FY10: 46052 | GF10: =SUM(GF9,GD10,-GE10) -> 0 | GG10: 46052 | GN10: =SUM(GN9,GL10,-GM10) -> 0 | GO10: 46068 | GV10: =SUM(GV9,GT10,-GU10) -> 0 | GW10: 46068 | HD10: =SUM(HD9,HB10,-HC10) -> 0 | HE10: 46068 | HL10: =SUM(HL9,HJ10,-HK10) -> 0 | HM10: 46068 | HT10: =SUM(HT9,HR10,-HS10) -> 0 | HU10: 46068 | IB10: =SUM(IB9,HZ10,-IA10) -> 0 | IC10: 46068 | IJ10: =SUM(IJ9,IH10,-II10) -> 0 | IK10: 46068 | IR10: =SUM(IR9,IP10,-IQ10) -> 0 | IS10: 46068 | IZ10: =SUM(IZ9,IX10,-IY10) -> 0 | JA10: 46068 | JH10: =SUM(JH9,JF10,-JG10) -> 0 | JI10: 46068 | JP10: =SUM(JP9,JN10,-JO10) -> 0 | JQ10: 46068 | JX10: =SUM(JX9,JV10,-JW10) -> 0 | JY10: 46068 | KF10: =SUM(KF9,KD10,-KE10) -> 0 | KG10: 46068 | KN10: =SUM(KN9,KL10,-KM10) -> 0 | KO10: 46068 | KV10: =SUM(KV9,KT10,-KU10) -> 0 | KW10: 46068 | LD10: =SUM(LD9,LB10,-LC10) -> 0 | LE10: 46068 | LL10: =SUM(LL9,LJ10,-LK10) -> 0 | LM10: 46068 | LT10: =SUM(LT9,LR10,-LS10) -> 0 | LU10: 46068 | MB10: =SUM(MB9,LZ10,-MA10) -> 0 | MC10: 46068 | MJ10: =SUM(MJ9,MH10,-MI10) -> 0 | MK10: 46068 | MR10: =SUM(MR9,MP10,-MQ10) -> 0 | MS10: 46068 | MZ10: =SUM(MZ9,MX10,-MY10) -> 0 | NA10: 46068 | NH10: =SUM(NH9,NF10,-NG10) -> 0 | NI10: 46068 | NP10: =SUM(NP9,NN10,-NO10) -> 0 | NQ10: 46068 | NX10: =SUM(NX9,NV10,-NW10) -> 0 | NY10: 46068 | OF10: =SUM(OF9,OD10,-OE10) -> 0 | OG10: 46068 | ON10: =SUM(ON9,OL10,-OM10) -> 0 | OO10: 46068 | OV10: =SUM(OV9,OT10,-OU10) -> 0 | OW10: 46068 | PD10: =SUM(PD9,PB10,-PC10) -> 0 | PE10: 46068 | PL10: =SUM(PL9,PJ10,-PK10) -> 0 | PM10: 46068 | PT10: =SUM(PT9,PR10,-PS10) -> 0 | PU10: 46068 | QB10: =SUM(QB9,PZ10,-QA10) -> 0 | QC10: 46068 | QJ10: =SUM(QJ9,QH10,-QI10) -> 0 | QK10: 46068 | QR10: =SUM(QR9,QP10,-QQ10) -> 0 | QS10: 46068 | QZ10: =SUM(QZ9,QX10,-QY10) -> 0 | RA10: 46068 | RH10: =SUM(RH9,RF10,-RG10) -> 0 | RI10: 46068 | RP10: =SUM(RP9,RN10,-RO10) -> 0 | RQ10: 46068 | RX10: =SUM(RX9,RV10,-RW10) -> 0 | RY10: 46068 | SF10: =SUM(SF9,SD10,-SE10) -> 0 | SG10: 46068 | SN10: =SUM(SN9,SL10,-SM10) -> 0 | SO10: 46068 | SV10: =SUM(SV9,ST10,-SU10) -> 0 | SW10: 46068 | TD10: =SUM(TD9,TB10,-TC10) -> 0 | TE10: 46068 | TL10: =SUM(TL9,TJ10,-TK10) -> 0 | TM10: 46068 | TT10: =SUM(TT9,TR10,-TS10) -> 0 | TU10: 46068 | UB10: =SUM(UB9,TZ10,-UA10) -> 0 | UC10: 46068 | UJ10: =SUM(UJ9,UH10,-UI10) -> 0 | UK10: 46068 | UR10: =SUM(UR9,UP10,-UQ10) -> 0 | US10: 46068 | UZ10: =SUM(UZ9,UX10,-UY10) -> 0 | VA10: 46068 | VH10: =SUM(VH9,VF10,-VG10) -> 0 | VI10: 46068 | VP10: =SUM(VP9,VN10,-VO10) -> 0 | VQ10: 46068 | VX10: =SUM(VX9,VV10,-VW10) -> 0 | VY10: 46068 | WF10: =SUM(WF9,WD10,-WE10) -> 0 | WG10: 46068 | WN10: =SUM(WN9,WL10,-WM10) -> 0 | WO10: 46068 | WV10: =SUM(WV9,WT10,-WU10) -> 0 | WW10: 46068 | XD10: =SUM(XD9,XB10,-XC10) -> 0 | XE10: 46068 | XL10: =SUM(XL9,XJ10,-XK10) -> 0 | XM10: 46068 | XT10: =SUM(XT9,XR10,-XS10) -> 0 | XU10: 46068 | YB10: =SUM(YB9,XZ10,-YA10) -> 0 | YC10: 46068 | YJ10: =SUM(YJ9,YH10,-YI10) -> 0 | YK10: 46068 | YR10: =SUM(YR9,YP10,-YQ10) -> 0 | YS10: 46068 | YZ10: =SUM(YZ9,YX10,-YY10) -> 0 | ZA10: 46068 | ZH10: =SUM(ZH9,ZF10,-ZG10) -> 0 | ZI10: 46068 | ZP10: =SUM(ZP9,ZN10,-ZO10) -> 0 | ZQ10: 46068 | ZX10: =SUM(ZX9,ZV10,-ZW10) -> 0 | ZY10: 46068 | AAF10: =SUM(AAF9,AAD10,-AAE10) -> 0 | AAG10: 46068 | AAN10: =SUM(AAN9,AAL10,-AAM10) -> 0 | AAO10: 46068 | AAV10: =SUM(AAV9,AAT10,-AAU10) -> 0 | AAW10: 46068 | ABD10: =SUM(ABD9,ABB10,-ABC10) -> 0 | ABE10: 46068 | ABL10: =SUM(ABL9,ABJ10,-ABK10) -> 0 | ABM10: 46068 | ABT10: =SUM(ABT9,ABR10,-ABS10) -> 0 | ABU10: 46068 | ACB10: =SUM(ACB9,ABZ10,-ACA10) -> 0 | ACC10: 46068
D11: =SUM(D10,B11,-C11) -> 1700 | E11: 46068 | L11: =SUM(L10,J11,-K11) -> 1000 | M11: 46068 | T11: =SUM(T10,R11,-S11) -> 4000 | U11: 46068 | AB11: =SUM(AB10,Z11,-AA11) -> 1000 | AC11: 46068 | AJ11: =SUM(AJ10,AH11,-AI11) -> 2000 | AK11: 46068 | AR11: =SUM(AR10,AP11,-AQ11) -> 1000 | AS11: 46068 | AZ11: =SUM(AZ10,AX11,-AY11) -> 1150 | BA11: 46068 | BH11: =SUM(BH10,BF11,-BG11) -> 7000 | BI11: 46068 | BP11: =SUM(BP10,BN11,-BO11) -> 1000 | BQ11: 46068 | BX11: =SUM(BX10,BV11,-BW11) -> 0 | BY11: 46068 | CF11: =SUM(CF10,CD11,-CE11) -> 0 | CG11: 46081 | CN11: =SUM(CN10,CL11,-CM11) -> 0 | CO11: 46081 | CV11: =SUM(CV10,CT11,-CU11) -> 0 | CW11: 46081 | DD11: =SUM(DD10,DB11,-DC11) -> 0 | DE11: 46081 | DL11: =SUM(DL10,DJ11,-DK11) -> 0 | DM11: 46068 | DT11: =SUM(DT10,DR11,-DS11) -> 0 | DU11: 46068 | EB11: =SUM(EB10,DZ11,-EA11) -> 0 | EC11: 46068 | EJ11: =SUM(EJ10,EH11,-EI11) -> 0 | EK11: 46068 | ER11: =SUM(ER10,EP11,-EQ11) -> 0 | ES11: 46068 | EZ11: =SUM(EZ10,EX11,-EY11) -> 0 | FA11: 46068 | FH11: =SUM(FH10,FF11,-FG11) -> 0 | FI11: 46068 | FP11: =SUM(FP10,FN11,-FO11) -> 0 | FQ11: 46068 | FX11: =SUM(FX10,FV11,-FW11) -> 0 | FY11: 46068 | GF11: =SUM(GF10,GD11,-GE11) -> 0 | GG11: 46068 | GN11: =SUM(GN10,GL11,-GM11) -> 0 | GO11: 46081 | GV11: =SUM(GV10,GT11,-GU11) -> 0 | GW11: 46081 | HD11: =SUM(HD10,HB11,-HC11) -> 0 | HE11: 46081 | HL11: =SUM(HL10,HJ11,-HK11) -> 0 | HM11: 46081 | HT11: =SUM(HT10,HR11,-HS11) -> 0 | HU11: 46081 | IB11: =SUM(IB10,HZ11,-IA11) -> 0 | IC11: 46081 | IJ11: =SUM(IJ10,IH11,-II11) -> 0 | IK11: 46081 | IR11: =SUM(IR10,IP11,-IQ11) -> 0 | IS11: 46081 | IZ11: =SUM(IZ10,IX11,-IY11) -> 0 | JA11: 46081 | JH11: =SUM(JH10,JF11,-JG11) -> 0 | JI11: 46081 | JP11: =SUM(JP10,JN11,-JO11) -> 0 | JQ11: 46081 | JX11: =SUM(JX10,JV11,-JW11) -> 0 | JY11: 46081 | KF11: =SUM(KF10,KD11,-KE11) -> 0 | KG11: 46081 | KN11: =SUM(KN10,KL11,-KM11) -> 0 | KO11: 46081 | KV11: =SUM(KV10,KT11,-KU11) -> 0 | KW11: 46081 | LD11: =SUM(LD10,LB11,-LC11) -> 0 | LE11: 46081 | LL11: =SUM(LL10,LJ11,-LK11) -> 0 | LM11: 46081 | LT11: =SUM(LT10,LR11,-LS11) -> 0 | LU11: 46081 | MB11: =SUM(MB10,LZ11,-MA11) -> 0 | MC11: 46081 | MJ11: =SUM(MJ10,MH11,-MI11) -> 0 | MK11: 46081 | MR11: =SUM(MR10,MP11,-MQ11) -> 0 | MS11: 46081 | MZ11: =SUM(MZ10,MX11,-MY11) -> 0 | NA11: 46081 | NH11: =SUM(NH10,NF11,-NG11) -> 0 | NI11: 46081 | NP11: =SUM(NP10,NN11,-NO11) -> 0 | NQ11: 46081 | NX11: =SUM(NX10,NV11,-NW11) -> 0 | NY11: 46081 | OF11: =SUM(OF10,OD11,-OE11) -> 0 | OG11: 46081 | ON11: =SUM(ON10,OL11,-OM11) -> 0 | OO11: 46081 | OV11: =SUM(OV10,OT11,-OU11) -> 0 | OW11: 46081 | PD11: =SUM(PD10,PB11,-PC11) -> 0 | PE11: 46081 | PL11: =SUM(PL10,PJ11,-PK11) -> 0 | PM11: 46081 | PT11: =SUM(PT10,PR11,-PS11) -> 0 | PU11: 46081 | QB11: =SUM(QB10,PZ11,-QA11) -> 0 | QC11: 46081 | QJ11: =SUM(QJ10,QH11,-QI11) -> 0 | QK11: 46081 | QR11: =SUM(QR10,QP11,-QQ11) -> 0 | QS11: 46081 | QZ11: =SUM(QZ10,QX11,-QY11) -> 0 | RA11: 46081 | RH11: =SUM(RH10,RF11,-RG11) -> 0 | RI11: 46081 | RP11: =SUM(RP10,RN11,-RO11) -> 0 | RQ11: 46081 | RX11: =SUM(RX10,RV11,-RW11) -> 0 | RY11: 46081 | SF11: =SUM(SF10,SD11,-SE11) -> 0 | SG11: 46081 | SN11: =SUM(SN10,SL11,-SM11) -> 0 | SO11: 46081 | SV11: =SUM(SV10,ST11,-SU11) -> 0 | SW11: 46081 | TD11: =SUM(TD10,TB11,-TC11) -> 0 | TE11: 46081 | TL11: =SUM(TL10,TJ11,-TK11) -> 0 | TM11: 46081 | TT11: =SUM(TT10,TR11,-TS11) -> 0 | TU11: 46081 | UB11: =SUM(UB10,TZ11,-UA11) -> 0 | UC11: 46081 | UJ11: =SUM(UJ10,UH11,-UI11) -> 0 | UK11: 46081 | UR11: =SUM(UR10,UP11,-UQ11) -> 0 | US11: 46081 | UZ11: =SUM(UZ10,UX11,-UY11) -> 0 | VA11: 46081 | VH11: =SUM(VH10,VF11,-VG11) -> 0 | VI11: 46081 | VP11: =SUM(VP10,VN11,-VO11) -> 0 | VQ11: 46081 | VX11: =SUM(VX10,VV11,-VW11) -> 0 | VY11: 46081 | WF11: =SUM(WF10,WD11,-WE11) -> 0 | WG11: 46081 | WN11: =SUM(WN10,WL11,-WM11) -> 0 | WO11: 46081 | WV11: =SUM(WV10,WT11,-WU11) -> 0 | WW11: 46081 | XD11: =SUM(XD10,XB11,-XC11) -> 0 | XE11: 46081 | XL11: =SUM(XL10,XJ11,-XK11) -> 0 | XM11: 46081 | XT11: =SUM(XT10,XR11,-XS11) -> 0 | XU11: 46081 | YB11: =SUM(YB10,XZ11,-YA11) -> 0 | YC11: 46081 | YJ11: =SUM(YJ10,YH11,-YI11) -> 0 | YK11: 46081 | YR11: =SUM(YR10,YP11,-YQ11) -> 0 | YS11: 46081 | YZ11: =SUM(YZ10,YX11,-YY11) -> 0 | ZA11: 46081 | ZH11: =SUM(ZH10,ZF11,-ZG11) -> 0 | ZI11: 46081 | ZP11: =SUM(ZP10,ZN11,-ZO11) -> 0 | ZQ11: 46081 | ZX11: =SUM(ZX10,ZV11,-ZW11) -> 0 | ZY11: 46081 | AAF11: =SUM(AAF10,AAD11,-AAE11) -> 0 | AAG11: 46081 | AAN11: =SUM(AAN10,AAL11,-AAM11) -> 0 | AAO11: 46081 | AAV11: =SUM(AAV10,AAT11,-AAU11) -> 0 | AAW11: 46081 | ABD11: =SUM(ABD10,ABB11,-ABC11) -> 0 | ABE11: 46081 | ABL11: =SUM(ABL10,ABJ11,-ABK11) -> 0 | ABM11: 46081 | ABT11: =SUM(ABT10,ABR11,-ABS11) -> 0 | ABU11: 46081 | ACB11: =SUM(ACB10,ABZ11,-ACA11) -> 0 | ACC11: 46081
D12: =SUM(D11,B12,-C12) -> 1700 | E12: 46081 | L12: =SUM(L11,J12,-K12) -> 1000 | M12: 46081 | T12: =SUM(T11,R12,-S12) -> 4000 | U12: 46081 | AB12: =SUM(AB11,Z12,-AA12) -> 1000 | AC12: 46081 | AJ12: =SUM(AJ11,AH12,-AI12) -> 2000 | AK12: 46081 | AR12: =SUM(AR11,AP12,-AQ12) -> 1000 | AS12: 46081 | AZ12: =SUM(AZ11,AX12,-AY12) -> 1150 | BA12: 46081 | BH12: =SUM(BH11,BF12,-BG12) -> 7000 | BI12: 46081 | BP12: =SUM(BP11,BN12,-BO12) -> 1000 | BQ12: 46081 | BX12: =SUM(BX11,BV12,-BW12) -> 0 | BY12: 46081 | CF12: =SUM(CF11,CD12,-CE12) -> 0 | CG12: 46096 | CN12: =SUM(CN11,CL12,-CM12) -> 0 | CO12: 46096 | CV12: =SUM(CV11,CT12,-CU12) -> 0 | CW12: 46096 | DD12: =SUM(DD11,DB12,-DC12) -> 0 | DE12: 46096 | DL12: =SUM(DL11,DJ12,-DK12) -> 0 | DM12: 46081 | DT12: =SUM(DT11,DR12,-DS12) -> 0 | DU12: 46081 | EB12: =SUM(EB11,DZ12,-EA12) -> 0 | EC12: 46081 | EJ12: =SUM(EJ11,EH12,-EI12) -> 0 | EK12: 46081 | ER12: =SUM(ER11,EP12,-EQ12) -> 0 | ES12: 46081 | EZ12: =SUM(EZ11,EX12,-EY12) -> 0 | FA12: 46081 | FH12: =SUM(FH11,FF12,-FG12) -> 0 | FI12: 46081 | FP12: =SUM(FP11,FN12,-FO12) -> 0 | FQ12: 46081 | FX12: =SUM(FX11,FV12,-FW12) -> 0 | FY12: 46081 | GF12: =SUM(GF11,GD12,-GE12) -> 0 | GG12: 46081 | GN12: =SUM(GN11,GL12,-GM12) -> 0 | GO12: 46096 | GV12: =SUM(GV11,GT12,-GU12) -> 0 | GW12: 46096 | HD12: =SUM(HD11,HB12,-HC12) -> 0 | HE12: 46096 | HL12: =SUM(HL11,HJ12,-HK12) -> 0 | HM12: 46096 | HT12: =SUM(HT11,HR12,-HS12) -> 0 | HU12: 46096 | IB12: =SUM(IB11,HZ12,-IA12) -> 0 | IC12: 46096 | IJ12: =SUM(IJ11,IH12,-II12) -> 0 | IK12: 46096 | IR12: =SUM(IR11,IP12,-IQ12) -> 0 | IS12: 46096 | IZ12: =SUM(IZ11,IX12,-IY12) -> 0 | JA12: 46096 | JH12: =SUM(JH11,JF12,-JG12) -> 0 | JI12: 46096 | JP12: =SUM(JP11,JN12,-JO12) -> 0 | JQ12: 46096 | JX12: =SUM(JX11,JV12,-JW12) -> 0 | JY12: 46096 | KF12: =SUM(KF11,KD12,-KE12) -> 0 | KG12: 46096 | KN12: =SUM(KN11,KL12,-KM12) -> 0 | KO12: 46096 | KV12: =SUM(KV11,KT12,-KU12) -> 0 | KW12: 46096 | LD12: =SUM(LD11,LB12,-LC12) -> 0 | LE12: 46096 | LL12: =SUM(LL11,LJ12,-LK12) -> 0 | LM12: 46096 | LT12: =SUM(LT11,LR12,-LS12) -> 0 | LU12: 46096 | MB12: =SUM(MB11,LZ12,-MA12) -> 0 | MC12: 46096 | MJ12: =SUM(MJ11,MH12,-MI12) -> 0 | MK12: 46096 | MR12: =SUM(MR11,MP12,-MQ12) -> 0 | MS12: 46096 | MZ12: =SUM(MZ11,MX12,-MY12) -> 0 | NA12: 46096 | NH12: =SUM(NH11,NF12,-NG12) -> 0 | NI12: 46096 | NP12: =SUM(NP11,NN12,-NO12) -> 0 | NQ12: 46096 | NX12: =SUM(NX11,NV12,-NW12) -> 0 | NY12: 46096 | OF12: =SUM(OF11,OD12,-OE12) -> 0 | OG12: 46096 | ON12: =SUM(ON11,OL12,-OM12) -> 0 | OO12: 46096 | OV12: =SUM(OV11,OT12,-OU12) -> 0 | OW12: 46096 | PD12: =SUM(PD11,PB12,-PC12) -> 0 | PE12: 46096 | PL12: =SUM(PL11,PJ12,-PK12) -> 0 | PM12: 46096 | PT12: =SUM(PT11,PR12,-PS12) -> 0 | PU12: 46096 | QB12: =SUM(QB11,PZ12,-QA12) -> 0 | QC12: 46096 | QJ12: =SUM(QJ11,QH12,-QI12) -> 0 | QK12: 46096 | QR12: =SUM(QR11,QP12,-QQ12) -> 0 | QS12: 46096 | QZ12: =SUM(QZ11,QX12,-QY12) -> 0 | RA12: 46096 | RH12: =SUM(RH11,RF12,-RG12) -> 0 | RI12: 46096 | RP12: =SUM(RP11,RN12,-RO12) -> 0 | RQ12: 46096 | RX12: =SUM(RX11,RV12,-RW12) -> 0 | RY12: 46096 | SF12: =SUM(SF11,SD12,-SE12) -> 0 | SG12: 46096 | SN12: =SUM(SN11,SL12,-SM12) -> 0 | SO12: 46096 | SV12: =SUM(SV11,ST12,-SU12) -> 0 | SW12: 46096 | TD12: =SUM(TD11,TB12,-TC12) -> 0 | TE12: 46096 | TL12: =SUM(TL11,TJ12,-TK12) -> 0 | TM12: 46096 | TT12: =SUM(TT11,TR12,-TS12) -> 0 | TU12: 46096 | UB12: =SUM(UB11,TZ12,-UA12) -> 0 | UC12: 46096 | UJ12: =SUM(UJ11,UH12,-UI12) -> 0 | UK12: 46096 | UR12: =SUM(UR11,UP12,-UQ12) -> 0 | US12: 46096 | UZ12: =SUM(UZ11,UX12,-UY12) -> 0 | VA12: 46096 | VH12: =SUM(VH11,VF12,-VG12) -> 0 | VI12: 46096 | VP12: =SUM(VP11,VN12,-VO12) -> 0 | VQ12: 46096 | VX12: =SUM(VX11,VV12,-VW12) -> 0 | VY12: 46096 | WF12: =SUM(WF11,WD12,-WE12) -> 0 | WG12: 46096 | WN12: =SUM(WN11,WL12,-WM12) -> 0 | WO12: 46096 | WV12: =SUM(WV11,WT12,-WU12) -> 0 | WW12: 46096 | XD12: =SUM(XD11,XB12,-XC12) -> 0 | XE12: 46096 | XL12: =SUM(XL11,XJ12,-XK12) -> 0 | XM12: 46096 | XT12: =SUM(XT11,XR12,-XS12) -> 0 | XU12: 46096 | YB12: =SUM(YB11,XZ12,-YA12) -> 0 | YC12: 46096 | YJ12: =SUM(YJ11,YH12,-YI12) -> 0 | YK12: 46096 | YR12: =SUM(YR11,YP12,-YQ12) -> 0 | YS12: 46096 | YZ12: =SUM(YZ11,YX12,-YY12) -> 0 | ZA12: 46096 | ZH12: =SUM(ZH11,ZF12,-ZG12) -> 0 | ZI12: 46096 | ZP12: =SUM(ZP11,ZN12,-ZO12) -> 0 | ZQ12: 46096 | ZX12: =SUM(ZX11,ZV12,-ZW12) -> 0 | ZY12: 46096 | AAF12: =SUM(AAF11,AAD12,-AAE12) -> 0 | AAG12: 46096 | AAN12: =SUM(AAN11,AAL12,-AAM12) -> 0 | AAO12: 46096 | AAV12: =SUM(AAV11,AAT12,-AAU12) -> 0 | AAW12: 46096 | ABD12: =SUM(ABD11,ABB12,-ABC12) -> 0 | ABE12: 46096 | ABL12: =SUM(ABL11,ABJ12,-ABK12) -> 0 | ABM12: 46096 | ABT12: =SUM(ABT11,ABR12,-ABS12) -> 0 | ABU12: 46096 | ACB12: =SUM(ACB11,ABZ12,-ACA12) -> 0 | ACC12: 46096
D13: =SUM(D12,B13,-C13) -> 1700 | E13: 46096 | L13: =SUM(L12,J13,-K13) -> 1000 | M13: 46096 | T13: =SUM(T12,R13,-S13) -> 4000 | U13: 46096 | AB13: =SUM(AB12,Z13,-AA13) -> 1000 | AC13: 46096 | AJ13: =SUM(AJ12,AH13,-AI13) -> 2000 | AK13: 46096 | AR13: =SUM(AR12,AP13,-AQ13) -> 1000 | AS13: 46096 | AZ13: =SUM(AZ12,AX13,-AY13) -> 1150 | BA13: 46096 | BH13: =SUM(BH12,BF13,-BG13) -> 7000 | BI13: 46096 | BP13: =SUM(BP12,BN13,-BO13) -> 1000 | BQ13: 46096 | BX13: =SUM(BX12,BV13,-BW13) -> 0 | BY13: 46096 | CF13: =SUM(CF12,CD13,-CE13) -> 0 | CG13: 46111 | CN13: =SUM(CN12,CL13,-CM13) -> 0 | CO13: 46111 | CV13: =SUM(CV12,CT13,-CU13) -> 0 | CW13: 46111 | DD13: =SUM(DD12,DB13,-DC13) -> 0 | DE13: 46111 | DL13: =SUM(DL12,DJ13,-DK13) -> 0 | DM13: 46096 | DT13: =SUM(DT12,DR13,-DS13) -> 0 | DU13: 46096 | EB13: =SUM(EB12,DZ13,-EA13) -> 0 | EC13: 46096 | EJ13: =SUM(EJ12,EH13,-EI13) -> 0 | EK13: 46096 | ER13: =SUM(ER12,EP13,-EQ13) -> 0 | ES13: 46096 | EZ13: =SUM(EZ12,EX13,-EY13) -> 0 | FA13: 46096 | FH13: =SUM(FH12,FF13,-FG13) -> 0 | FI13: 46096 | FP13: =SUM(FP12,FN13,-FO13) -> 0 | FQ13: 46096 | FX13: =SUM(FX12,FV13,-FW13) -> 0 | FY13: 46096 | GF13: =SUM(GF12,GD13,-GE13) -> 0 | GG13: 46096 | GN13: =SUM(GN12,GL13,-GM13) -> 0 | GO13: 46111 | GV13: =SUM(GV12,GT13,-GU13) -> 0 | GW13: 46111 | HD13: =SUM(HD12,HB13,-HC13) -> 0 | HE13: 46111 | HL13: =SUM(HL12,HJ13,-HK13) -> 0 | HM13: 46111 | HT13: =SUM(HT12,HR13,-HS13) -> 0 | HU13: 46111 | IB13: =SUM(IB12,HZ13,-IA13) -> 0 | IC13: 46111 | IJ13: =SUM(IJ12,IH13,-II13) -> 0 | IK13: 46111 | IR13: =SUM(IR12,IP13,-IQ13) -> 0 | IS13: 46111 | IZ13: =SUM(IZ12,IX13,-IY13) -> 0 | JA13: 46111 | JH13: =SUM(JH12,JF13,-JG13) -> 0 | JI13: 46111 | JP13: =SUM(JP12,JN13,-JO13) -> 0 | JQ13: 46111 | JX13: =SUM(JX12,JV13,-JW13) -> 0 | JY13: 46111 | KF13: =SUM(KF12,KD13,-KE13) -> 0 | KG13: 46111 | KN13: =SUM(KN12,KL13,-KM13) -> 0 | KO13: 46111 | KV13: =SUM(KV12,KT13,-KU13) -> 0 | KW13: 46111 | LD13: =SUM(LD12,LB13,-LC13) -> 0 | LE13: 46111 | LL13: =SUM(LL12,LJ13,-LK13) -> 0 | LM13: 46111 | LT13: =SUM(LT12,LR13,-LS13) -> 0 | LU13: 46111 | MB13: =SUM(MB12,LZ13,-MA13) -> 0 | MC13: 46111 | MJ13: =SUM(MJ12,MH13,-MI13) -> 0 | MK13: 46111 | MR13: =SUM(MR12,MP13,-MQ13) -> 0 | MS13: 46111 | MZ13: =SUM(MZ12,MX13,-MY13) -> 0 | NA13: 46111 | NH13: =SUM(NH12,NF13,-NG13) -> 0 | NI13: 46111 | NP13: =SUM(NP12,NN13,-NO13) -> 0 | NQ13: 46111 | NX13: =SUM(NX12,NV13,-NW13) -> 0 | NY13: 46111 | OF13: =SUM(OF12,OD13,-OE13) -> 0 | OG13: 46111 | ON13: =SUM(ON12,OL13,-OM13) -> 0 | OO13: 46111 | OV13: =SUM(OV12,OT13,-OU13) -> 0 | OW13: 46111 | PD13: =SUM(PD12,PB13,-PC13) -> 0 | PE13: 46111 | PL13: =SUM(PL12,PJ13,-PK13) -> 0 | PM13: 46111 | PT13: =SUM(PT12,PR13,-PS13) -> 0 | PU13: 46111 | QB13: =SUM(QB12,PZ13,-QA13) -> 0 | QC13: 46111 | QJ13: =SUM(QJ12,QH13,-QI13) -> 0 | QK13: 46111 | QR13: =SUM(QR12,QP13,-QQ13) -> 0 | QS13: 46111 | QZ13: =SUM(QZ12,QX13,-QY13) -> 0 | RA13: 46111 | RH13: =SUM(RH12,RF13,-RG13) -> 0 | RI13: 46111 | RP13: =SUM(RP12,RN13,-RO13) -> 0 | RQ13: 46111 | RX13: =SUM(RX12,RV13,-RW13) -> 0 | RY13: 46111 | SF13: =SUM(SF12,SD13,-SE13) -> 0 | SG13: 46111 | SN13: =SUM(SN12,SL13,-SM13) -> 0 | SO13: 46111 | SV13: =SUM(SV12,ST13,-SU13) -> 0 | SW13: 46111 | TD13: =SUM(TD12,TB13,-TC13) -> 0 | TE13: 46111 | TL13: =SUM(TL12,TJ13,-TK13) -> 0 | TM13: 46111 | TT13: =SUM(TT12,TR13,-TS13) -> 0 | TU13: 46111 | UB13: =SUM(UB12,TZ13,-UA13) -> 0 | UC13: 46111 | UJ13: =SUM(UJ12,UH13,-UI13) -> 0 | UK13: 46111 | UR13: =SUM(UR12,UP13,-UQ13) -> 0 | US13: 46111 | UZ13: =SUM(UZ12,UX13,-UY13) -> 0 | VA13: 46111 | VH13: =SUM(VH12,VF13,-VG13) -> 0 | VI13: 46111 | VP13: =SUM(VP12,VN13,-VO13) -> 0 | VQ13: 46111 | VX13: =SUM(VX12,VV13,-VW13) -> 0 | VY13: 46111 | WF13: =SUM(WF12,WD13,-WE13) -> 0 | WG13: 46111 | WN13: =SUM(WN12,WL13,-WM13) -> 0 | WO13: 46111 | WV13: =SUM(WV12,WT13,-WU13) -> 0 | WW13: 46111 | XD13: =SUM(XD12,XB13,-XC13) -> 0 | XE13: 46111 | XL13: =SUM(XL12,XJ13,-XK13) -> 0 | XM13: 46111 | XT13: =SUM(XT12,XR13,-XS13) -> 0 | XU13: 46111 | YB13: =SUM(YB12,XZ13,-YA13) -> 0 | YC13: 46111 | YJ13: =SUM(YJ12,YH13,-YI13) -> 0 | YK13: 46111 | YR13: =SUM(YR12,YP13,-YQ13) -> 0 | YS13: 46111 | YZ13: =SUM(YZ12,YX13,-YY13) -> 0 | ZA13: 46111 | ZH13: =SUM(ZH12,ZF13,-ZG13) -> 0 | ZI13: 46111 | ZP13: =SUM(ZP12,ZN13,-ZO13) -> 0 | ZQ13: 46111 | ZX13: =SUM(ZX12,ZV13,-ZW13) -> 0 | ZY13: 46111 | AAF13: =SUM(AAF12,AAD13,-AAE13) -> 0 | AAG13: 46111 | AAN13: =SUM(AAN12,AAL13,-AAM13) -> 0 | AAO13: 46111 | AAV13: =SUM(AAV12,AAT13,-AAU13) -> 0 | AAW13: 46111 | ABD13: =SUM(ABD12,ABB13,-ABC13) -> 0 | ABE13: 46111 | ABL13: =SUM(ABL12,ABJ13,-ABK13) -> 0 | ABM13: 46111 | ABT13: =SUM(ABT12,ABR13,-ABS13) -> 0 | ABU13: 46111 | ACB13: =SUM(ACB12,ABZ13,-ACA13) -> 0 | ACC13: 46111
D14: =SUM(D13,B14,-C14) -> 1700 | E14: 46111 | L14: =SUM(L13,J14,-K14) -> 1000 | M14: 46111 | T14: =SUM(T13,R14,-S14) -> 4000 | U14: 46111 | AB14: =SUM(AB13,Z14,-AA14) -> 1000 | AC14: 46111 | AJ14: =SUM(AJ13,AH14,-AI14) -> 2000 | AK14: 46111 | AR14: =SUM(AR13,AP14,-AQ14) -> 1000 | AS14: 46111 | AZ14: =SUM(AZ13,AX14,-AY14) -> 1150 | BA14: 46111 | BH14: =SUM(BH13,BF14,-BG14) -> 7000 | BI14: 46111 | BP14: =SUM(BP13,BN14,-BO14) -> 1000 | BQ14: 46111 | BX14: =SUM(BX13,BV14,-BW14) -> 0 | BY14: 46111 | CF14: =SUM(CF13,CD14,-CE14) -> 0 | CG14: 46127 | CN14: =SUM(CN13,CL14,-CM14) -> 0 | CO14: 46127 | CV14: =SUM(CV13,CT14,-CU14) -> 0 | CW14: 46127 | DD14: =SUM(DD13,DB14,-DC14) -> 0 | DE14: 46127 | DL14: =SUM(DL13,DJ14,-DK14) -> 0 | DM14: 46111 | DT14: =SUM(DT13,DR14,-DS14) -> 0 | DU14: 46111 | EB14: =SUM(EB13,DZ14,-EA14) -> 0 | EC14: 46111 | EJ14: =SUM(EJ13,EH14,-EI14) -> 0 | EK14: 46111 | ER14: =SUM(ER13,EP14,-EQ14) -> 0 | ES14: 46111 | EZ14: =SUM(EZ13,EX14,-EY14) -> 0 | FA14: 46111 | FH14: =SUM(FH13,FF14,-FG14) -> 0 | FI14: 46111 | FP14: =SUM(FP13,FN14,-FO14) -> 0 | FQ14: 46111 | FX14: =SUM(FX13,FV14,-FW14) -> 0 | FY14: 46111 | GF14: =SUM(GF13,GD14,-GE14) -> 0 | GG14: 46111 | GN14: =SUM(GN13,GL14,-GM14) -> 0 | GO14: 46127 | GV14: =SUM(GV13,GT14,-GU14) -> 0 | GW14: 46127 | HD14: =SUM(HD13,HB14,-HC14) -> 0 | HE14: 46127 | HL14: =SUM(HL13,HJ14,-HK14) -> 0 | HM14: 46127 | HT14: =SUM(HT13,HR14,-HS14) -> 0 | HU14: 46127 | IB14: =SUM(IB13,HZ14,-IA14) -> 0 | IC14: 46127 | IJ14: =SUM(IJ13,IH14,-II14) -> 0 | IK14: 46127 | IR14: =SUM(IR13,IP14,-IQ14) -> 0 | IS14: 46127 | IZ14: =SUM(IZ13,IX14,-IY14) -> 0 | JA14: 46127 | JH14: =SUM(JH13,JF14,-JG14) -> 0 | JI14: 46127 | JP14: =SUM(JP13,JN14,-JO14) -> 0 | JQ14: 46127 | JX14: =SUM(JX13,JV14,-JW14) -> 0 | JY14: 46127 | KF14: =SUM(KF13,KD14,-KE14) -> 0 | KG14: 46127 | KN14: =SUM(KN13,KL14,-KM14) -> 0 | KO14: 46127 | KV14: =SUM(KV13,KT14,-KU14) -> 0 | KW14: 46127 | LD14: =SUM(LD13,LB14,-LC14) -> 0 | LE14: 46127 | LL14: =SUM(LL13,LJ14,-LK14) -> 0 | LM14: 46127 | LT14: =SUM(LT13,LR14,-LS14) -> 0 | LU14: 46127 | MB14: =SUM(MB13,LZ14,-MA14) -> 0 | MC14: 46127 | MJ14: =SUM(MJ13,MH14,-MI14) -> 0 | MK14: 46127 | MR14: =SUM(MR13,MP14,-MQ14) -> 0 | MS14: 46127 | MZ14: =SUM(MZ13,MX14,-MY14) -> 0 | NA14: 46127 | NH14: =SUM(NH13,NF14,-NG14) -> 0 | NI14: 46127 | NP14: =SUM(NP13,NN14,-NO14) -> 0 | NQ14: 46127 | NX14: =SUM(NX13,NV14,-NW14) -> 0 | NY14: 46127 | OF14: =SUM(OF13,OD14,-OE14) -> 0 | OG14: 46127 | ON14: =SUM(ON13,OL14,-OM14) -> 0 | OO14: 46127 | OV14: =SUM(OV13,OT14,-OU14) -> 0 | OW14: 46127 | PD14: =SUM(PD13,PB14,-PC14) -> 0 | PE14: 46127 | PL14: =SUM(PL13,PJ14,-PK14) -> 0 | PM14: 46127 | PT14: =SUM(PT13,PR14,-PS14) -> 0 | PU14: 46127 | QB14: =SUM(QB13,PZ14,-QA14) -> 0 | QC14: 46127 | QJ14: =SUM(QJ13,QH14,-QI14) -> 0 | QK14: 46127 | QR14: =SUM(QR13,QP14,-QQ14) -> 0 | QS14: 46127 | QZ14: =SUM(QZ13,QX14,-QY14) -> 0 | RA14: 46127 | RH14: =SUM(RH13,RF14,-RG14) -> 0 | RI14: 46127 | RP14: =SUM(RP13,RN14,-RO14) -> 0 | RQ14: 46127 | RX14: =SUM(RX13,RV14,-RW14) -> 0 | RY14: 46127 | SF14: =SUM(SF13,SD14,-SE14) -> 0 | SG14: 46127 | SN14: =SUM(SN13,SL14,-SM14) -> 0 | SO14: 46127 | SV14: =SUM(SV13,ST14,-SU14) -> 0 | SW14: 46127 | TD14: =SUM(TD13,TB14,-TC14) -> 0 | TE14: 46127 | TL14: =SUM(TL13,TJ14,-TK14) -> 0 | TM14: 46127 | TT14: =SUM(TT13,TR14,-TS14) -> 0 | TU14: 46127 | UB14: =SUM(UB13,TZ14,-UA14) -> 0 | UC14: 46127 | UJ14: =SUM(UJ13,UH14,-UI14) -> 0 | UK14: 46127 | UR14: =SUM(UR13,UP14,-UQ14) -> 0 | US14: 46127 | UZ14: =SUM(UZ13,UX14,-UY14) -> 0 | VA14: 46127 | VH14: =SUM(VH13,VF14,-VG14) -> 0 | VI14: 46127 | VP14: =SUM(VP13,VN14,-VO14) -> 0 | VQ14: 46127 | VX14: =SUM(VX13,VV14,-VW14) -> 0 | VY14: 46127 | WF14: =SUM(WF13,WD14,-WE14) -> 0 | WG14: 46127 | WN14: =SUM(WN13,WL14,-WM14) -> 0 | WO14: 46127 | WV14: =SUM(WV13,WT14,-WU14) -> 0 | WW14: 46127 | XD14: =SUM(XD13,XB14,-XC14) -> 0 | XE14: 46127 | XL14: =SUM(XL13,XJ14,-XK14) -> 0 | XM14: 46127 | XT14: =SUM(XT13,XR14,-XS14) -> 0 | XU14: 46127 | YB14: =SUM(YB13,XZ14,-YA14) -> 0 | YC14: 46127 | YJ14: =SUM(YJ13,YH14,-YI14) -> 0 | YK14: 46127 | YR14: =SUM(YR13,YP14,-YQ14) -> 0 | YS14: 46127 | YZ14: =SUM(YZ13,YX14,-YY14) -> 0 | ZA14: 46127 | ZH14: =SUM(ZH13,ZF14,-ZG14) -> 0 | ZI14: 46127 | ZP14: =SUM(ZP13,ZN14,-ZO14) -> 0 | ZQ14: 46127 | ZX14: =SUM(ZX13,ZV14,-ZW14) -> 0 | ZY14: 46127 | AAF14: =SUM(AAF13,AAD14,-AAE14) -> 0 | AAG14: 46127 | AAN14: =SUM(AAN13,AAL14,-AAM14) -> 0 | AAO14: 46127 | AAV14: =SUM(AAV13,AAT14,-AAU14) -> 0 | AAW14: 46127 | ABD14: =SUM(ABD13,ABB14,-ABC14) -> 0 | ABE14: 46127 | ABL14: =SUM(ABL13,ABJ14,-ABK14) -> 0 | ABM14: 46127 | ABT14: =SUM(ABT13,ABR14,-ABS14) -> 0 | ABU14: 46127 | ACB14: =SUM(ACB13,ABZ14,-ACA14) -> 0 | ACC14: 46127
D15: =SUM(D14,B15,-C15) -> 1700 | E15: 46127 | L15: =SUM(L14,J15,-K15) -> 1000 | M15: 46127 | T15: =SUM(T14,R15,-S15) -> 4000 | U15: 46127 | AB15: =SUM(AB14,Z15,-AA15) -> 1000 | AC15: 46127 | AJ15: =SUM(AJ14,AH15,-AI15) -> 2000 | AK15: 46127 | AR15: =SUM(AR14,AP15,-AQ15) -> 1000 | AS15: 46127 | AZ15: =SUM(AZ14,AX15,-AY15) -> 1150 | BA15: 46127 | BH15: =SUM(BH14,BF15,-BG15) -> 7000 | BI15: 46127 | BP15: =SUM(BP14,BN15,-BO15) -> 1000 | BQ15: 46127 | BX15: =SUM(BX14,BV15,-BW15) -> 0 | BY15: 46127 | CF15: =SUM(CF14,CD15,-CE15) -> 0 | CG15: 46142 | CN15: =SUM(CN14,CL15,-CM15) -> 0 | CO15: 46142 | CV15: =SUM(CV14,CT15,-CU15) -> 0 | CW15: 46142 | DD15: =SUM(DD14,DB15,-DC15) -> 0 | DE15: 46142 | DL15: =SUM(DL14,DJ15,-DK15) -> 0 | DM15: 46127 | DT15: =SUM(DT14,DR15,-DS15) -> 0 | DU15: 46127 | EB15: =SUM(EB14,DZ15,-EA15) -> 0 | EC15: 46127 | EJ15: =SUM(EJ14,EH15,-EI15) -> 0 | EK15: 46127 | ER15: =SUM(ER14,EP15,-EQ15) -> 0 | ES15: 46127 | EZ15: =SUM(EZ14,EX15,-EY15) -> 0 | FA15: 46127 | FH15: =SUM(FH14,FF15,-FG15) -> 0 | FI15: 46127 | FP15: =SUM(FP14,FN15,-FO15) -> 0 | FQ15: 46127 | FX15: =SUM(FX14,FV15,-FW15) -> 0 | FY15: 46127 | GF15: =SUM(GF14,GD15,-GE15) -> 0 | GG15: 46127 | GN15: =SUM(GN14,GL15,-GM15) -> 0 | GO15: 46142 | GV15: =SUM(GV14,GT15,-GU15) -> 0 | GW15: 46142 | HD15: =SUM(HD14,HB15,-HC15) -> 0 | HE15: 46142 | HL15: =SUM(HL14,HJ15,-HK15) -> 0 | HM15: 46142 | HT15: =SUM(HT14,HR15,-HS15) -> 0 | HU15: 46142 | IB15: =SUM(IB14,HZ15,-IA15) -> 0 | IC15: 46142 | IJ15: =SUM(IJ14,IH15,-II15) -> 0 | IK15: 46142 | IR15: =SUM(IR14,IP15,-IQ15) -> 0 | IS15: 46142 | IZ15: =SUM(IZ14,IX15,-IY15) -> 0 | JA15: 46142 | JH15: =SUM(JH14,JF15,-JG15) -> 0 | JI15: 46142 | JP15: =SUM(JP14,JN15,-JO15) -> 0 | JQ15: 46142 | JX15: =SUM(JX14,JV15,-JW15) -> 0 | JY15: 46142 | KF15: =SUM(KF14,KD15,-KE15) -> 0 | KG15: 46142 | KN15: =SUM(KN14,KL15,-KM15) -> 0 | KO15: 46142 | KV15: =SUM(KV14,KT15,-KU15) -> 0 | KW15: 46142 | LD15: =SUM(LD14,LB15,-LC15) -> 0 | LE15: 46142 | LL15: =SUM(LL14,LJ15,-LK15) -> 0 | LM15: 46142 | LT15: =SUM(LT14,LR15,-LS15) -> 0 | LU15: 46142 | MB15: =SUM(MB14,LZ15,-MA15) -> 0 | MC15: 46142 | MJ15: =SUM(MJ14,MH15,-MI15) -> 0 | MK15: 46142 | MR15: =SUM(MR14,MP15,-MQ15) -> 0 | MS15: 46142 | MZ15: =SUM(MZ14,MX15,-MY15) -> 0 | NA15: 46142 | NH15: =SUM(NH14,NF15,-NG15) -> 0 | NI15: 46142 | NP15: =SUM(NP14,NN15,-NO15) -> 0 | NQ15: 46142 | NX15: =SUM(NX14,NV15,-NW15) -> 0 | NY15: 46142 | OF15: =SUM(OF14,OD15,-OE15) -> 0 | OG15: 46142 | ON15: =SUM(ON14,OL15,-OM15) -> 0 | OO15: 46142 | OV15: =SUM(OV14,OT15,-OU15) -> 0 | OW15: 46142 | PD15: =SUM(PD14,PB15,-PC15) -> 0 | PE15: 46142 | PL15: =SUM(PL14,PJ15,-PK15) -> 0 | PM15: 46142 | PT15: =SUM(PT14,PR15,-PS15) -> 0 | PU15: 46142 | QB15: =SUM(QB14,PZ15,-QA15) -> 0 | QC15: 46142 | QJ15: =SUM(QJ14,QH15,-QI15) -> 0 | QK15: 46142 | QR15: =SUM(QR14,QP15,-QQ15) -> 0 | QS15: 46142 | QZ15: =SUM(QZ14,QX15,-QY15) -> 0 | RA15: 46142 | RH15: =SUM(RH14,RF15,-RG15) -> 0 | RI15: 46142 | RP15: =SUM(RP14,RN15,-RO15) -> 0 | RQ15: 46142 | RX15: =SUM(RX14,RV15,-RW15) -> 0 | RY15: 46142 | SF15: =SUM(SF14,SD15,-SE15) -> 0 | SG15: 46142 | SN15: =SUM(SN14,SL15,-SM15) -> 0 | SO15: 46142 | SV15: =SUM(SV14,ST15,-SU15) -> 0 | SW15: 46142 | TD15: =SUM(TD14,TB15,-TC15) -> 0 | TE15: 46142 | TL15: =SUM(TL14,TJ15,-TK15) -> 0 | TM15: 46142 | TT15: =SUM(TT14,TR15,-TS15) -> 0 | TU15: 46142 | UB15: =SUM(UB14,TZ15,-UA15) -> 0 | UC15: 46142 | UJ15: =SUM(UJ14,UH15,-UI15) -> 0 | UK15: 46142 | UR15: =SUM(UR14,UP15,-UQ15) -> 0 | US15: 46142 | UZ15: =SUM(UZ14,UX15,-UY15) -> 0 | VA15: 46142 | VH15: =SUM(VH14,VF15,-VG15) -> 0 | VI15: 46142 | VP15: =SUM(VP14,VN15,-VO15) -> 0 | VQ15: 46142 | VX15: =SUM(VX14,VV15,-VW15) -> 0 | VY15: 46142 | WF15: =SUM(WF14,WD15,-WE15) -> 0 | WG15: 46142 | WN15: =SUM(WN14,WL15,-WM15) -> 0 | WO15: 46142 | WV15: =SUM(WV14,WT15,-WU15) -> 0 | WW15: 46142 | XD15: =SUM(XD14,XB15,-XC15) -> 0 | XE15: 46142 | XL15: =SUM(XL14,XJ15,-XK15) -> 0 | XM15: 46142 | XT15: =SUM(XT14,XR15,-XS15) -> 0 | XU15: 46142 | YB15: =SUM(YB14,XZ15,-YA15) -> 0 | YC15: 46142 | YJ15: =SUM(YJ14,YH15,-YI15) -> 0 | YK15: 46142 | YR15: =SUM(YR14,YP15,-YQ15) -> 0 | YS15: 46142 | YZ15: =SUM(YZ14,YX15,-YY15) -> 0 | ZA15: 46142 | ZH15: =SUM(ZH14,ZF15,-ZG15) -> 0 | ZI15: 46142 | ZP15: =SUM(ZP14,ZN15,-ZO15) -> 0 | ZQ15: 46142 | ZX15: =SUM(ZX14,ZV15,-ZW15) -> 0 | ZY15: 46142 | AAF15: =SUM(AAF14,AAD15,-AAE15) -> 0 | AAG15: 46142 | AAN15: =SUM(AAN14,AAL15,-AAM15) -> 0 | AAO15: 46142 | AAV15: =SUM(AAV14,AAT15,-AAU15) -> 0 | AAW15: 46142 | ABD15: =SUM(ABD14,ABB15,-ABC15) -> 0 | ABE15: 46142 | ABL15: =SUM(ABL14,ABJ15,-ABK15) -> 0 | ABM15: 46142 | ABT15: =SUM(ABT14,ABR15,-ABS15) -> 0 | ABU15: 46142 | ACB15: =SUM(ACB14,ABZ15,-ACA15) -> 0 | ACC15: 46142
